Workbook

Sheet Guía y metodología
B2: Matriz de Identificación y Valoración de Riesgos
B3: SiempreSoft · Enfoque basado en eventos (ISO/IEC 27005:2022, Anexo A)
B5: 1. Dos ejes de clasificación: Origen vs. Categoría
B6: "Origen del riesgo" (Deliberado / Accidental-humano / Accidental-técnico / Ambiental) responde a QUIÉN o QUÉ dispara la amenaza — es la taxonomía de fuente de riesgo del Anexo A/B de ISO/IEC 27005:2022, que solo reconoce 3 orígenes (D/A/E, igual que tu hoja "Amenazas"): una falla técnica no es intencional ni ambiental, así que cae dentro de "Accidental" — aquí se subdivide en humano/técnico solo como ayuda operativa para saber qué tipo de control aplicar. "Categoría de riesgo" (Estratégico, Financiero, Operativo, Tecnológico, Legal/Normativo, Reputacional, Político) responde a EN QUÉ ÁMBITO DE NEGOCIO impacta — es la clasificación que usan COSO ERM / ISO 31000 para reportar a la dirección. Son ejes independientes: un mismo riesgo puede ser Origen=Deliberado + Categoría=Financiero (un estafador que busca beneficio económico), u Origen=Accidental-técnico + Categoría=Tecnológico (falla de Azure). Se agregó una columna nueva para cada eje en la hoja "Matriz de riesgos".
B8: 2. Catálogo de fuentes/amenazas por origen
B9: Las 8 categorías de fuente de riesgo deliberada (Relacionado a estados, Crimen organizado, Terrorista, Activista ideológico, Cibermercenario, Aficionado, Vengador, Agresor patológico) son el catálogo FIJO del Anexo A de ISO/IEC 27005:2022 — no es un límite que se haya impuesto, es la lista textual del estándar. Para los orígenes Accidental, Ambiental y Técnico existe otro catálogo, el de tipos de amenaza (Anexo B), que ya tenías cargado en tu hoja "Amenazas" con 72 entradas agrupadas en 7 tipos (física, eventos naturales, falla de infraestructura, fallas técnicas, acciones humanas, compromiso de funciones, amenazas organizacionales). En "Datos maestros" se agregó una tabla resumen de esos 7 tipos con ejemplos, que remite a tu catálogo completo para el detalle.
B11: 3. Matriz de nivel de riesgo (se mantiene 5×4)
B12: Se decidió mantener la matriz tal como la tienes (Consecuencia 5 niveles × Probabilidad 4 niveles), ya que la usan en otros documentos del SGSI. Nota para consistencia futura: si en algún momento migran a una matriz simétrica (5×5) o a un puntaje semicuantitativo, solo hay que actualizar la tabla H de "Datos maestros" — la fórmula de Nivel de riesgo en la matriz ya está preparada para leer de ahí sin tocar cada fila.
B14: 4. Qué cambia respecto a tu archivo original
B15: ● Fuente de riesgo vs. causa técnica
B16: En tu archivo, "Fuente de riesgo" mezclaba el agente (ej. "Organización criminal") con la causa técnica (ej. "Ausencia de pruebas en staging"). Se separó en "Origen del riesgo" (clasificado automáticamente, en cursiva gris — valídalo) y "Fuente de riesgo (causa u origen específico)" con tu texto original.
B17: ● DES solo aplica a orígenes deliberados
... B24: 5. Estructura del archivo
B25: Guía y metodología | C25: Esta hoja.
B26: Datos maestros | C26: Listas desplegables: procesos, origen del riesgo, categoría de riesgo, categorías de fuente deliberada (Anexo A), tipos de amenaza por origen A/E/T (Anexo B), motivaciones/DES, objetivos meta, escalas de consecuencia y probabilidad con criterios, matriz 5×4, propietarios, tratamiento y estados.
B27: Matriz de riesgos | C27: Identificación y valoración de los 56 riesgos existentes reorganizados + 20 filas en blanco. Nivel de riesgo y estado de completitud son fórmulas automáticas.
B28: Mapa de calor | C28: Conteo automático de riesgos por celda de la matriz 5×4, coloreado como heat map.
B30: 6. Leyenda de colores
C31: Celda pendiente de completar (dato que falta en tu archivo original o fila nueva).
C32: Celda calculada por fórmula — no editar a mano.
B33: Cursiva gris | C33: Origen o categoría sugeridos automáticamente a partir del texto original — valídalos.
B35: 7. Subsanación Obs.2 de auditoría (6.1.3 — pestaña de tratamiento separada y vinculada)
B36: El auditor observó que el tratamiento de riesgos debía ir en una pestaña propia, separada de la identificación/análisis/evaluación, y vinculada a ella. Se creó la hoja "Tratamiento de riesgos": cada fila referencia un ID de la "Matriz de riesgos" mediante un desplegable (no texto libre), y el Proceso y el Nivel de riesgo se traen automáticamente con VLOOKUP — si cambias la evaluación de un riesgo, su tratamiento se actualiza solo. En la "Matriz de riesgos" se retiraron las columnas de tratamiento (Opción, Estado, Observaciones) y se dejó una sola columna "¿Tiene tratamiento asignado?" que verifica contra la hoja nueva — se resalta en rojo cuando un riesgo Alto o Muy alto no tiene tratamiento registrado, para que puedas priorizar antes de la próxima auditoría. Se importaron los 16 tratamientos que ya tenías documentados (R06, R16, R23, R28, R29, R35, R39, R40, R42–R46, R48–R50); los de "Riesgos de Proyectos" (PY0x) no aplican a esta matriz y siguen en tu hoja original.

Sheet Datos maestros
A1: DATOS MAESTROS · listas desplegables y escalas de la matriz de riesgos
A3: A. Procesos
A4: Proceso
A5: Revisión por la Dirección
A6: Validación de comprobantes OSE
A7: Gestion Comercial
A8: Gestión del éxito y atención del cliente
A9: Ingenieria y calidad de sofware
A10: Gestion de operaciones
A11: Recursos humanos
A12: Fscturación y cobranza
A13: Logística
... A17: B. Origen del riesgo (¿quién/qué lo origina? — Anexo A ISO/IEC 27005:2022)
A18: Origen | B18: Descripción
A19: Deliberado (humano intencional) | B19: Actor con intención consciente de causar daño u obtener beneficio (ciberdelincuentes, competidores, clientes hostiles, personal con intención maliciosa). Aquí sí aplica el DES / motivación.
A20: Accidental - humano (error no intencional) | B20: Subtipo de "Accidental" (código A del Anexo B). Error humano, falta de capacitación, procesos manuales, negligencia sin intención de dañar.
A21: Técnico (falla de sistema/infraestructura) | B21: Subtipo de "Accidental" (código A del Anexo B). El estándar no distingue un origen "Técnico" aparte: una falla de sistema no es intencional (no es D) ni viene del entorno físico (no es E), así que cae en Accidental. Se separa aquí solo como ayuda operativa, para diferenciar el control a aplicar (automatización/redundancia vs. capacitación/doble validación). Fallas de hardware/software, obsolescencia, configuración, capacidad, dependencia de terceros tecnológicos (ej. Azure).
A22: Ambiental | B22: Fenómenos naturales o climáticos: lluvias, inundaciones, sismos, descargas eléctricas. Código E del Anexo B.
A24: C. Categoría de riesgo (¿en qué ámbito de negocio impacta? — estilo COSO ERM / ISO 31000)
A25: Categoría | B25: Descripción
A26: Estratégico | B26: Afecta objetivos de negocio, crecimiento, mercado o modelo de negocio a mediano/largo plazo.
A27: Financiero | B27: Pérdida económica directa, costos, flujo de caja, cobranza, crédito, fraude con impacto monetario.
A28: Operativo | B28: Afecta la ejecución diaria de procesos: producción, soporte, calidad, capacidad, continuidad.
A29: Tecnológico | B29: Fallas o debilidades de sistemas, infraestructura, software, datos, ciberseguridad.
A30: Legal / Normativo | B30: Incumplimiento normativo, multas, sanciones, pérdida de autorización (SUNAT, PSE, OSE).
A31: Reputacional | B31: Daño a la imagen, confianza del cliente, quejas públicas, pérdida de credibilidad.
A32: Político | B32: Cambios regulatorios de origen gubernamental, relaciones con entidades públicas, entorno político/país.
A34: D. Categorías de fuente de riesgo DELIBERADA (catálogo fijo, Anexo A ISO/IEC 27005:2022)
A35: Categoría de fuente | B35: Actores típicos | C35: Método de ataque típico
A36: Relacionado a estados | B36: Estados, agencias de inteligencia | C36: Ataques dirigidos, profesionales, calendario predefinido (cadena de suministro).
A37: Crimen organizado | B37: Mafias, pandillas, organizaciones cibercriminales | C37: Estafas, ransomware, botnets, con fines lucrativos.
A38: Terrorista | B38: Ciber-terroristas, ciber-milicias | C38: Ataques poco sofisticados pero destructivos: denegación de servicio.
A39: Activista ideológico | B39: Ciber-hacktivistas, grupos de interés | C39: Similar al terrorista pero con intención menos destructiva (transmite una ideología).
A40: Cibermercenario | B40: Hackers especializados que crean kits/herramientas | C40: Diseño y venta de kits de ataque disponibles en línea.
A41: Aficionado | B41: Script-kiddies con buenos conocimientos informáticos | C41: Ataques básicos usando kits de ataque disponibles en línea.
A42: Vengador | B42: Ex-empleado, proveedor descontento | C42: Determinación y conocimiento interno de sistemas y procesos.
A43: Agresor patológico | B43: Competidor desleal, cliente deshonesto, estafador | C43: Base de conocimiento informático o subcontratación del ataque.
A45: E. Catálogo de amenazas para orígenes Accidental / Ambiental / Técnico (Anexo B ISO/IEC 27005:2022, tomado íntegro de tu hoja "Amenazas")
A46: A diferencia de "Deliberado" (que sí tiene su propio catálogo de actores en la tabla D, porque hay una intención humana caracterizable), el estándar NO define categorías de "fuente" separadas para Accidental/Ambiental/Técnico. En su lugar usa un catálogo único de amenazas (Anexo B), diferenciado por la columna Origen (D=deliberada, A=accidental, E=ambiental) — porque una misma amenaza puede tener más de un origen (ej. "Fuego" puede ser accidental, deliberado o ambiental a la vez). "Técnico" no es un código del estándar: es una subdivisión práctica que agregamos marcando en la columna ¿Técnico? las filas de los tipos "Fallas técnicas" y "Falla de infraestructura". Usa el autofiltro de Excel en esta tabla para quedarte solo con las filas que te interesan.
A48: Código | B48: Amenaza | C48: Tipo | D48: Origen (D/A/E) | E48: ¿Técnico?
...

Sheet Matriz de riesgos
A1: Matriz de Identificación y Valoración de Riesgos — SiempreSoft (enfoque basado en eventos)
A2: DOCUMENTO PARA: SGSI · ÁREA: SEGURIDAD DE LA INFORMACIÓN · NIVEL DE CONFIDENCIALIDAD: USO INTERNO · El tratamiento de riesgos se gestiona en la hoja "Tratamiento de riesgos" (vinculada por ID)
B3: Identificación del riesgo | I3: Evaluación del riesgo | N3: Seguimiento
A4: ID | B4: Proceso | C4: Origen del riesgo | D4: Categoría de riesgo | E4: Fuente de riesgo (causa u origen específico) | F4: Evento | G4: Estado final deseado / Motivación (DES) (solo si el origen es deliberado) | H4: Escenario estratégico | I4: Consecuencia | J4: Probabilidad | K4: Nivel de riesgo | L4: Controles existentes | M4: Propietario del riesgo | N4: ¿Tiene tratamiento asignado? | O4: Estado del registro
A5: R01 | B5: Ambos | C5: Deliberado (humano intencional) | D5: Financiero | E5: Organización criminal | F5: Divulgación de la información | G5: Obtener beneficios económicos | H5: Extorsión | I5: 5 - Catastrófico | J5: 2 – Bastante improbable | K5: =IF(OR(I5="",J5=""),"",INDEX('Datos maestros'!$B$153:$F$156,VALUE(LEFT(J5,1)),VALUE(LEFT(I5,1)))) -> Medio | L5: Política de control de accesos, Procedimiento para trabajo en áreas seguras, Política de claves | M5: Gerente general | N5: =IF(A5="","",IF(COUNTIF('Tratamiento de riesgos'!$B:$B,A5)>0,"Sí","No")) -> No | O5: =IF(SUM(COUNTBLANK(B5:C5),COUNTBLANK(E5:F5),COUNTBLANK(I5:J5),COUNTBLANK(M5))>0,"⚠ Pendiente de completar","✓ Completo") -> ✓ Completo
A6: R02 | B6: Facturación electrónica PSE | C6: Deliberado (humano intencional) | D6: Financiero | E6: Competidor desleal | F6: Venta del servicio/sistema en competencia bajo costo (ERP) | G6: Obtener monopolio de mercado | H6: Eliminación de competidores | I6: 2 - Significativo | J6: 3 - Probable | K6: =IF(OR(I6="",J6=""),"",INDEX('Datos maestros'!$B$153:$F$156,VALUE(LEFT(J6,1)),VALUE(LEFT(I6,1)))) -> Bajo | M6: Gerente general | N6: =IF(A6="","",IF(COUNTIF('Tratamiento de riesgos'!$B:$B,A6)>0,"Sí","No")) -> No | O6: =IF(SUM(COUNTBLANK(B6:C6),COUNTBLANK(E6:F6),COUNTBLANK(I6:J6),COUNTBLANK(M6))>0,"⚠ Pendiente de completar","✓ Completo") -> ✓ Completo
A7: R03 | B7: Facturación electrónica PSE | C7: Deliberado (humano intencional) | D7: Reputacional | E7: Cliente descontento | F7: Mal trato al servicio de soporte / Quejas exageradas y constantes | G7: Anular el contrato | H7: Mala reputación | I7: 2 - Significativo | J7: 3 - Probable | K7: =IF(OR(I7="",J7=""),"",INDEX('Datos maestros'!$B$153:$F$156,VALUE(LEFT(J7,1)),VALUE(LEFT(I7,1)))) -> Bajo | L7: Procedimiento de atención al cliente | M7: Jefe de Soporte al cliente | N7: =IF(A7="","",IF(COUNTIF('Tratamiento de riesgos'!$B:$B,A7)>0,"Sí","No")) -> No | O7: =IF(SUM(COUNTBLANK(B7:C7),COUNTBLANK(E7:F7),COUNTBLANK(I7:J7),COUNTBLANK(M7))>0,"⚠ Pendiente de completar","✓ Completo") -> ✓ Completo
A8: R04 | B8: Ambos | C8: Deliberado (humano intencional) | D8: Financiero | E8: Estafador | F8: Correos spam / Facturas falsas / Enlaces suplantados o clonados | G8: Obtener beneficios económicos | H8: Pérdida económica | I8: 3 - Serio | J8: 2 – Bastante improbable | K8: =IF(OR(I8="",J8=""),"",INDEX('Datos maestros'!$B$153:$F$156,VALUE(LEFT(J8,1)),VALUE(LEFT(I8,1)))) -> Bajo | L8: Política de control de accesos, Procedimiento para trabajo en áreas seguras, Política de claves | M8: Gerente general | N8: =IF(A8="","",IF(COUNTIF('Tratamiento de riesgos'!$B:$B,A8)>0,"Sí","No")) -> No | O8: =IF(SUM(COUNTBLANK(B8:C8),COUNTBLANK(E8:F8),COUNTBLANK(I8:J8),COUNTBLANK(M8))>0,"⚠ Pendiente de completar","✓ Completo") -> ✓ Completo
A9: R05 | B9: Validación de comprobantes OSE | C9: Deliberado (humano intencional) | D9: Tecnológico | E9: Ataque a los servicios/web con WAF | F9: Ataque por saturación de CPU | G9: Adquirir un vector de ataque | H9: Denegación de los servicios Autenticación/OSE | I9: 4 - Crítico | J9: 2 – Bastante improbable | K9: =IF(OR(I9="",J9=""),"",INDEX('Datos maestros'!$B$153:$F$156,VALUE(LEFT(J9,1)),VALUE(LEFT(I9,1)))) -> Medio | L9: Procedimientos operativos de TI y de la comunicación, Directivas WAF, Revisión de monitor de azure | M9: Jefe de Producción | N9: =IF(A9="","",IF(COUNTIF('Tratamiento de riesgos'!$B:$B,A9)>0,"Sí","No")) -> No | O9: =IF(SUM(COUNTBLANK(B9:C9),COUNTBLANK(E9:F9),COUNTBLANK(I9:J9),COUNTBLANK(M9))>0,"⚠ Pendiente de completar","✓ Completo") -> ✓ Completo
A10: R06 | B10: Facturación electrónica PSE | C10: Accidental - técnico (falla de sistema/infraestructura) | D10: Tecnológico | E10: Acceso a los servicios sin WAF (ERP) | F10: Falta de autenticación de doble factor (token de autenticación) | G10: Acceder al sistema en el ambiente del cliente | H10: Accesos no autorizado | I10: 4 - Crítico | J10: 3 - Probable | K10: =IF(OR(I10="",J10=""),"",INDEX('Datos maestros'!$B$153:$F$156,VALUE(LEFT(J10,1)),VALUE(LEFT(I10,1)))) -> Alto | M10: Jefe de Desarrollo | N10: =IF(A10="","",IF(COUNTIF('Tratamiento de riesgos'!$B:$B,A10)>0,"Sí","No")) -> Sí | O10: =IF(SUM(COUNTBLANK(B10:C10),COUNTBLANK(E10:F10),COUNTBLANK(I10:J10),COUNTBLANK(M10))>0,"⚠ Pendiente de completar","✓ Completo") -> ✓ Completo
A11: R07 | B11: Ambos | C11: Ambiental | D11: Operativo | E11: Fenómenos climáticos | F11: Inundación en zonas expuestas | G11: Indisponibilidad del personal | H11: Lluvias intensas | I11: 2 - Significativo | J11: 3 - Probable | K11: =IF(OR(I11="",J11=""),"",INDEX('Datos maestros'!$B$153:$F$156,VALUE(LEFT(J11,1)),VALUE(LEFT(I11,1)))) -> Bajo | L11: Planes de recuperación ante desastre | M11: Jefe de Producción | N11: =IF(A11="","",IF(COUNTIF('Tratamiento de riesgos'!$B:$B,A11)>0,"Sí","No")) -> No | O11: =IF(SUM(COUNTBLANK(B11:C11),COUNTBLANK(E11:F11),COUNTBLANK(I11:J11),COUNTBLANK(M11))>0,"⚠ Pendiente de completar","✓ Completo") -> ✓ Completo
A12: R08 | B12: Facturación electrónica PSE | C12: Ambiental | D12: Tecnológico | E12: Fenómenos climáticos | F12: Descarga electrica | G12: Indisponibilidad de energía/red | H12: Corte de energía/red prolongado | I12: 3 - Serio | J12: 2 – Bastante improbable | K12: =IF(OR(I12="",J12=""),"",INDEX('Datos maestros'!$B$153:$F$156,VALUE(LEFT(J12,1)),VALUE(LEFT(I12,1)))) -> Bajo | L12: Planes de recuperación ante desastre | M12: Asistente Administrativo | N12: =IF(A12="","",IF(COUNTIF('Tratamiento de riesgos'!$B:$B,A12)>0,"Sí","No")) -> No | O12: =IF(SUM(COUNTBLANK(B12:C12),COUNTBLANK(E12:F12),COUNTBLANK(I12:J12),COUNTBLANK(M12))>0,"⚠ Pendiente de completar","✓ Completo") -> ✓ Completo
A13: R09 | B13: Ambos | C13: Accidental - técnico (falla de sistema/infraestructura) | D13: Tecnológico | E13: Centro de datos en azure | F13: Problemas que afectan los productos y servicios críticos del ERP y OSE | G13: Indisponibilidad en la infraestructura tecnológica | H13: Caída en los recursos de azure | I13: 3 - Serio | J13: 2 – Bastante improbable | K13: =IF(OR(I13="",J13=""),"",INDEX('Datos maestros'!$B$153:$F$156,VALUE(LEFT(J13,1)),VALUE(LEFT(I13,1)))) -> Bajo | L13: Plan de recuperación ante desastre | M13: Gerente general | N13: =IF(A13="","",IF(COUNTIF('Tratamiento de riesgos'!$B:$B,A13)>0,"Sí","No")) -> No | O13: =IF(SUM(COUNTBLANK(B13:C13),COUNTBLANK(E13:F13),COUNTBLANK(I13:J13),COUNTBLANK(M13))>0,"⚠ Pendiente de completar","✓ Completo") -> ✓ Completo
A14: R10 | B14: Facturación electrónica PSE | C14: Accidental - técnico (falla de sistema/infraestructura) | D14: Tecnológico | E14: Productos externos sin soporte en linea | F14: Mensajes de error / Interrupción del software | G14: No afectarse economicamente / Desinterés | H14: Paralización en la cadena de suministros de las TIC | I14: 2 - Significativo | J14: 3 - Probable | K14: =IF(OR(I14="",J14=""),"",INDEX('Datos maestros'!$B$153:$F$156,VALUE(LEFT(J14,1)),VALUE(LEFT(I14,1)))) -> Bajo | L14: Política de gestión de cambios | M14: Jefe de Producción | N14: =IF(A14="","",IF(COUNTIF('Tratamiento de riesgos'!$B:$B,A14)>0,"Sí","No")) -> No | O14: =IF(SUM(COUNTBLANK(B14:C14),COUNTBLANK(E14:F14),COUNTBLANK(I14:J14),COUNTBLANK(M14))>0,"⚠ Pendiente de completar","✓ Completo") -> ✓ Completo
A15: R11 | B15: Validación de comprobantes OSE | C15: Accidental - técnico (falla de sistema/infraestructura) | D15: Legal / Normativo | E15: Excepciones no controladas en el OSE | F15: No devuelve CDR/acuse de recibo | G15: Indisponibilidad del servicio | H15: Caída del servicio de SUNAT | I15: 2 - Significativo | J15: 3 - Probable | K15: =IF(OR(I15="",J15=""),"",INDEX('Datos maestros'!$B$153:$F$156,VALUE(LEFT(J15,1)),VALUE(LEFT(I15,1)))) -> Bajo | L15: Procedimiento (SEE - OSE) para la validación de comprobantes | M15: Jefe de Soporte al cliente | N15: =IF(A15="","",IF(COUNTIF('Tratamiento de riesgos'!$B:$B,A15)>0,"Sí","No")) -> No | O15: =IF(SUM(COUNTBLANK(B15:C15),COUNTBLANK(E15:F15),COUNTBLANK(I15:J15),COUNTBLANK(M15))>0,"⚠ Pendiente de completar","✓ Completo") -> ✓ Completo
A16: R12 | B16: Validación de comprobantes OSE | C16: Accidental - técnico (falla de sistema/infraestructura) | D16: Operativo | E16: Excepciones no controladas en el OSE | F16: No devuelve CDR | G16: Indisponibilidad del servicio | H16: Caída del servicio OSE SIEMPRESOFT | I16: 3 - Serio | J16: 2 – Bastante improbable | K16: =IF(OR(I16="",J16=""),"",INDEX('Datos maestros'!$B$153:$F$156,VALUE(LEFT(J16,1)),VALUE(LEFT(I16,1)))) -> Bajo | L16: Procedimiento (SEE - OSE) para la validación de comprobantes | M16: Operador OSE | N16: =IF(A16="","",IF(COUNTIF('Tratamiento de riesgos'!$B:$B,A16)>0,"Sí","No")) -> No | O16: =IF(SUM(COUNTBLANK(B16:C16),COUNTBLANK(E16:F16),COUNTBLANK(I16:J16),COUNTBLANK(M16))>0,"⚠ Pendiente de completar","✓ Completo") -> ✓ Completo
A17: R13 | B17: Facturación electrónica PSE | C17: Accidental - humano (error no intencional) | D17: Operativo | E17: Trabajadores no concientizados | F17: Daño/infeccción el equipo móvil o cómputo | G17: No adoptar conductas de seguridad | H17: Indisponibilidad de los equipos de computo (robo, virus, daño) | I17: 3 - Serio | J17: 2 – Bastante improbable | K17: =IF(OR(I17="",J17=""),"",INDEX('Datos maestros'!$B$153:$F$156,VALUE(LEFT(J17,1)),VALUE(LEFT(I17,1)))) -> Bajo | L17: Plan de capacitación y concienciación anual, Configuración endpoint | M17: Oficial de Seguridad de la información | N17: =IF(A17="","",IF(COUNTIF('Tratamiento de riesgos'!$B:$B,A17)>0,"Sí","No")) -> No | O17: =IF(SUM(COUNTBLANK(B17:C17),COUNTBLANK(E17:F17),COUNTBLANK(I17:J17),COUNTBLANK(M17))>0,"⚠ Pendiente de completar","✓ Completo") -> ✓ Completo
A18: R14 | B18: Facturación electrónica PSE | C18: Accidental - humano (error no intencional) | D18: Operativo | E18: Trabajadores no concientizados | F18: Exponer datos personales/comprobantes electrónicos de los clientes | G18: Violación a la identidad/privacidad | H18: Mal uso de los datos personales/Reserva tributaria | I18: 4 - Crítico | J18: 2 – Bastante improbable | K18: =IF(OR(I18="",J18=""),"",INDEX('Datos maestros'!$B$153:$F$156,VALUE(LEFT(J18,1)),VALUE(LEFT(I18,1)))) -> Medio | L18: Plan de capacitación y concienciación anual | M18: Oficial de Seguridad de la información | N18: =IF(A18="","",IF(COUNTIF('Tratamiento de riesgos'!$B:$B,A18)>0,"Sí","No")) -> No | O18: =IF(SUM(COUNTBLANK(B18:C18),COUNTBLANK(E18:F18),COUNTBLANK(I18:J18),COUNTBLANK(M18))>0,"⚠ Pendiente de completar","✓ Completo") -> ✓ Completo
A19: R15 | B19: Facturación electrónica PSE | C19: Accidental - humano (error no intencional) | D19: Operativo | E19: Trabajadores no concientizados | F19: Descarga electrica, golpe severo, corte con vidrio | G19: Daño corporal | H19: Accidente de trabajo | I19: 4 - Crítico | J19: 1 - Improbable | K19: =IF(OR(I19="",J19=""),"",INDEX('Datos maestros'!$B$153:$F$156,VALUE(LEFT(J19,1)),VALUE(LEFT(I19,1)))) -> Bajo | L19: Capacitación en seguridad y salud en el trabajo | M19: Servicio de SST | N19: =IF(A19="","",IF(COUNTIF('Tratamiento de riesgos'!$B:$B,A19)>0,"Sí","No")) -> No | O19: =IF(SUM(COUNTBLANK(B19:C19),COUNTBLANK(E19:F19),COUNTBLANK(I19:J19),COUNTBLANK(M19))>0,"⚠ Pendiente de completar","✓ Completo") -> ✓ Completo
A20: R16 | B20: Validación de comprobantes OSE | C20: Accidental - humano (error no intencional) | D20: Tecnológico | E20: Falta de revisiones periódicas | F20: Bloqueo directivas WAF, espacio de disco lleno, consumo de cpu del VM, caída de servicio IIS | G20: Interrupción del sistema/servicio | H20: Fallas y bloqueos en el sistema/servicio | I20: 4 - Crítico | J20: 3 - Probable | K20: =IF(OR(I20="",J20=""),"",INDEX('Datos maestros'!$B$153:$F$156,VALUE(LEFT(J20,1)),VALUE(LEFT(I20,1)))) -> Alto | L20: Procedimientos operativos de TI y de la comunicación, Revisión del servidor VM y monitor de azure | M20: Asistente de Producción | N20: =IF(A20="","",IF(COUNTIF('Tratamiento de riesgos'!$B:$B,A20)>0,"Sí","No")) -> Sí | O20: =IF(SUM(COUNTBLANK(B20:C20),COUNTBLANK(E20:F20),COUNTBLANK(I20:J20),COUNTBLANK(M20))>0,"⚠ Pendiente de completar","✓ Completo") -> ✓ Completo
A21: R17 | B21: Facturación electrónica PSE | C21: Accidental - técnico (falla de sistema/infraestructura) | D21: Tecnológico | E21: Antiguedad del App services | F21: Aplicativos web no tienen la última versión del catcha | G21: Interrupción del sistema/servicio | H21: Fallas y bloqueos en el sistema/servicio | I21: 3 - Serio | J21: 3 - Probable | K21: =IF(OR(I21="",J21=""),"",INDEX('Datos maestros'!$B$153:$F$156,VALUE(LEFT(J21,1)),VALUE(LEFT(I21,1)))) -> Medio | M21: Jefe de Desarrollo | N21: =IF(A21="","",IF(COUNTIF('Tratamiento de riesgos'!$B:$B,A21)>0,"Sí","No")) -> No | O21: =IF(SUM(COUNTBLANK(B21:C21),COUNTBLANK(E21:F21),COUNTBLANK(I21:J21),COUNTBLANK(M21))>0,"⚠ Pendiente de completar","✓ Completo") -> ✓ Completo
A22: R18 | B22: Facturación electrónica PSE | C22: Accidental - técnico (falla de sistema/infraestructura) | D22: Operativo | E22: Usuarios con privilegios elevados | F22: Eliminación/modificación de informacion sensible | G22: Pérdida irrecuperable de la información | H22: Mal uso de los derechos | I22: 3 - Serio | J22: 2 – Bastante improbable | K22: =IF(OR(I22="",J22=""),"",INDEX('Datos maestros'!$B$153:$F$156,VALUE(LEFT(J22,1)),VALUE(LEFT(I22,1)))) -> Bajo | L22: Política de control de accesos | M22: Jefe de Soporte al cliente | N22: =IF(A22="","",IF(COUNTIF('Tratamiento de riesgos'!$B:$B,A22)>0,"Sí","No")) -> No | O22: =IF(SUM(COUNTBLANK(B22:C22),COUNTBLANK(E22:F22),COUNTBLANK(I22:J22),COUNTBLANK(M22))>0,"⚠ Pendiente de completar","✓ Completo") -> ✓ Completo
A23: R19 | B23: Facturación electrónica PSE | C23: Accidental - técnico (falla de sistema/infraestructura) | D23: Tecnológico | E23: Infraestructura como servicio | F23: Interrupción de los servicios (servidores virtuales, red) | G23: Indisponibilidad del servicio | H23: Incumplimiento del SLA | I23: 3 - Serio | J23: 3 - Probable | K23: =IF(OR(I23="",J23=""),"",INDEX('Datos maestros'!$B$153:$F$156,VALUE(LEFT(J23,1)),VALUE(LEFT(I23,1)))) -> Medio | L23: Procedimiento para el análisis de requerimiento | M23: Jefe de Desarrollo | N23: =IF(A23="","",IF(COUNTIF('Tratamiento de riesgos'!$B:$B,A23)>0,"Sí","No")) -> No | O23: =IF(SUM(COUNTBLANK(B23:C23),COUNTBLANK(E23:F23),COUNTBLANK(I23:J23),COUNTBLANK(M23))>0,"⚠ Pendiente de completar","✓ Completo") -> ✓ Completo
A24: R20 | B24: Facturación electrónica PSE | C24: Accidental - técnico (falla de sistema/infraestructura) | D24: Operativo | E24: Recomendaciones limitadas | F24: Recomendaciones muy restrictivas, riesgo en la implementación | G24: Exposición a vulnerabilidades | H24: No lograr la puntuación de seguridad en los puntos de conexión | I24: 2 - Significativo | J24: 3 - Probable | K24: =IF(OR(I24="",J24=""),"",INDEX('Datos maestros'!$B$153:$F$156,VALUE(LEFT(J24,1)),VALUE(LEFT(I24,1)))) -> Bajo | L24: Reunión con la alta dirección | M24: Jefe de Producción | N24: =IF(A24="","",IF(COUNTIF('Tratamiento de riesgos'!$B:$B,A24)>0,"Sí","No")) -> No | O24: =IF(SUM(COUNTBLANK(B24:C24),COUNTBLANK(E24:F24),COUNTBLANK(I24:J24),COUNTBLANK(M24))>0,"⚠ Pendiente de completar","✓ Completo") -> ✓ Completo
A25: R21 | B25: Facturación electrónica PSE | C25: Accidental - técnico (falla de sistema/infraestructura) | D25: Financiero | E25: Recomendaciones limitadas | F25: Recomendaciones muy costosas/restrictivas, riesgo en la implementación | G25: Exposición a vulnerabilidades | H25: No lograr la puntuación de seguridad en los recursos de la nube | I25: 2 - Significativo | J25: 3 - Probable | K25: =IF(OR(I25="",J25=""),"",INDEX('Datos maestros'!$B$153:$F$156,VALUE(LEFT(J25,1)),VALUE(LEFT(I25,1)))) -> Bajo | L25: Reunión con la alta dirección | M25: Jefe de Producción | N25: =IF(A25="","",IF(COUNTIF('Tratamiento de riesgos'!$B:$B,A25)>0,"Sí","No")) -> No | O25: =IF(SUM(COUNTBLANK(B25:C25),COUNTBLANK(E25:F25),COUNTBLANK(I25:J25),COUNTBLANK(M25))>0,"⚠ Pendiente de completar","✓ Completo") -> ✓ Completo
A26: R22 | B26: Facturación electrónica PSE | C26: Accidental - técnico (falla de sistema/infraestructura) | D26: Legal / Normativo | E26: Incumplimiento normativo como PSE | F26: Incumplimiento de las obligaciones de la RS 199-2015/SUNAT | G26: Incumplimiento de los OSI | H26: Multas o Sanciones | I26: 4 - Crítico | J26: 1 - Improbable | K26: =IF(OR(I26="",J26=""),"",INDEX('Datos maestros'!$B$153:$F$156,VALUE(LEFT(J26,1)),VALUE(LEFT(I26,1)))) -> Bajo | L26: Revisón de auditoría interna | M26: Oficial de Seguridad de la información | N26: =IF(A26="","",IF(COUNTIF('Tratamiento de riesgos'!$B:$B,A26)>0,"Sí","No")) -> No | O26: =IF(SUM(COUNTBLANK(B26:C26),COUNTBLANK(E26:F26),COUNTBLANK(I26:J26),COUNTBLANK(M26))>0,"⚠ Pendiente de completar","✓ Completo") -> ✓ Completo
A27: R23 | B27: Validación de comprobantes OSE | C27: Accidental - técnico (falla de sistema/infraestructura) | D27: Legal / Normativo | E27: Incumplimiento normativo como OSE | F27: Incumplimiento de las obligaciones de la RS 117-2017/SUNAT | G27: Incumplimiento de los OSI | H27: Multas o Sanciones | I27: 4 - Crítico | J27: 3 - Probable | K27: =IF(OR(I27="",J27=""),"",INDEX('Datos maestros'!$B$153:$F$156,VALUE(LEFT(J27,1)),VALUE(LEFT(I27,1)))) -> Alto | L27: Revisón de auditoría interna | M27: Oficial de Seguridad de la información | N27: =IF(A27="","",IF(COUNTIF('Tratamiento de riesgos'!$B:$B,A27)>0,"Sí","No")) -> Sí | O27: =IF(SUM(COUNTBLANK(B27:C27),COUNTBLANK(E27:F27),COUNTBLANK(I27:J27),COUNTBLANK(M27))>0,"⚠ Pendiente de completar","✓ Completo") -> ✓ Completo
A28: R24 | B28: Validación de comprobantes OSE | C28: Accidental - humano (error no intencional) | D28: Operativo | E28: Conocimiento centralizado en una persona | F28: No existe procedimientos e instructivos documentados del proceso | G28: Superar el tiempo de recuperación objetivo - ROT | H28: No se puede activar el plan de recuperación ante desastre en la plataforma | I28: 3 - Serio | J28: 3 - Probable | K28: =IF(OR(I28="",J28=""),"",INDEX('Datos maestros'!$B$153:$F$156,VALUE(LEFT(J28,1)),VALUE(LEFT(I28,1)))) -> Medio | L28: Manuales OSE Capacitación en CosmosDB | M28: Jefe de Desarrollo | N28: =IF(A28="","",IF(COUNTIF('Tratamiento de riesgos'!$B:$B,A28)>0,"Sí","No")) -> No | O28: =IF(SUM(COUNTBLANK(B28:C28),COUNTBLANK(E28:F28),COUNTBLANK(I28:J28),COUNTBLANK(M28))>0,"⚠ Pendiente de completar","✓ Completo") -> ✓ Completo
A29: R25 | B29: Validación de comprobantes OSE | C29: Accidental - humano (error no intencional) | D29: Operativo | E29: Conocimiento centralizado en una persona | F29: No existe reemplazo del Desarrollador OSE | G29: Retraso o error en la validación/envío de comprobantes electrónicos | H29: Defectos, fallas o errores en el servicio OSE y sus componentes principales | I29: 3 - Serio | J29: 3 - Probable | K29: =IF(OR(I29="",J29=""),"",INDEX('Datos maestros'!$B$153:$F$156,VALUE(LEFT(J29,1)),VALUE(LEFT(I29,1)))) -> Medio | M29: Jefe de Desarrollo | N29: =IF(A29="","",IF(COUNTIF('Tratamiento de riesgos'!$B:$B,A29)>0,"Sí","No")) -> No | O29: =IF(SUM(COUNTBLANK(B29:C29),COUNTBLANK(E29:F29),COUNTBLANK(I29:J29),COUNTBLANK(M29))>0,"⚠ Pendiente de completar","✓ Completo") -> ✓ Completo
A30: R26 | B30: Facturación electrónica PSE | C30: Accidental - técnico (falla de sistema/infraestructura) | D30: Tecnológico | E30: ERP sin interfaz web | F30: Dependencia del instalador de escritorio | G30: Clientes insatisfechos | H30: Pérdida de clientes | I30: 2 - Significativo | J30: 4 – Muy probable | K30: =IF(OR(I30="",J30=""),"",INDEX('Datos maestros'!$B$153:$F$156,VALUE(LEFT(J30,1)),VALUE(LEFT(I30,1)))) -> Medio | M30: Jefe de Desarrollo | N30: =IF(A30="","",IF(COUNTIF('Tratamiento de riesgos'!$B:$B,A30)>0,"Sí","No")) -> No | O30: =IF(SUM(COUNTBLANK(B30:C30),COUNTBLANK(E30:F30),COUNTBLANK(I30:J30),COUNTBLANK(M30))>0,"⚠ Pendiente de completar","✓ Completo") -> ✓ Completo
A31: R27 | B31: Facturación electrónica PSE | C31: Accidental - técnico (falla de sistema/infraestructura) | D31: Operativo | E31: Falta de reportería/análsis de datos | F31: Reportes incompletos | G31: Clientes insatisfechos | H31: Pérdida de clientes | I31: 3 - Serio | J31: 3 - Probable | K31: =IF(OR(I31="",J31=""),"",INDEX('Datos maestros'!$B$153:$F$156,VALUE(LEFT(J31,1)),VALUE(LEFT(I31,1)))) -> Medio | M31: Jefe de Desarrollo | N31: =IF(A31="","",IF(COUNTIF('Tratamiento de riesgos'!$B:$B,A31)>0,"Sí","No")) -> No | O31: =IF(SUM(COUNTBLANK(B31:C31),COUNTBLANK(E31:F31),COUNTBLANK(I31:J31),COUNTBLANK(M31))>0,"⚠ Pendiente de completar","✓ Completo") -> ✓ Completo
A32: R28 | B32: Validación de comprobantes OSE | C32: Accidental - técnico (falla de sistema/infraestructura) | D32: Legal / Normativo | E32: HSM de Keyvault | F32: Servicio no cuenta con los dos estándares de cumplimiento | G32: Adquirir el servicio en otra nube mas costosa | H32: Multas o Sanciones | I32: 3 - Serio | J32: 4 – Muy probable | K32: =IF(OR(I32="",J32=""),"",INDEX('Datos maestros'!$B$153:$F$156,VALUE(LEFT(J32,1)),VALUE(LEFT(I32,1)))) -> Alto | L32: Keyvault | M32: Gerente general | N32: =IF(A32="","",IF(COUNTIF('Tratamiento de riesgos'!$B:$B,A32)>0,"Sí","No")) -> Sí | O32: =IF(SUM(COUNTBLANK(B32:C32),COUNTBLANK(E32:F32),COUNTBLANK(I32:J32),COUNTBLANK(M32))>0,"⚠ Pendiente de completar","✓ Completo") -> ✓ Completo
A33: R29 | B33: Facturación electrónica PSE | C33: Accidental - técnico (falla de sistema/infraestructura) | D33: Legal / Normativo | E33: Errores del sistema/humanos | F33: Superar el 5% de comprobantes electrónicos rechazados | G33: No se puede ejercer la actividad de facturación electrónica en el sistema SIEMPRESOFT ERP | H33: Multas o Sanciones | I33: 4 - Crítico | J33: 3 - Probable | K33: =IF(OR(I33="",J33=""),"",INDEX('Datos maestros'!$B$153:$F$156,VALUE(LEFT(J33,1)),VALUE(LEFT(I33,1)))) -> Alto | L33: Plan de acción de OSI | M33: Gerente general | N33: =IF(A33="","",IF(COUNTIF('Tratamiento de riesgos'!$B:$B,A33)>0,"Sí","No")) -> Sí | O33: =IF(SUM(COUNTBLANK(B33:C33),COUNTBLANK(E33:F33),COUNTBLANK(I33:J33),COUNTBLANK(M33))>0,"⚠ Pendiente de completar","✓ Completo") -> ✓ Completo
A34: R30 | B34: Ambos | C34: Accidental - técnico (falla de sistema/infraestructura) | D34: Operativo | E34: Recursos en la nube | F34: Denegación de servicio / Divulgación de la información | G34: Interrupción del sistema/servicio | H34: Ataque cibernético | I34: 3 - Serio | J34: 2 – Bastante improbable | K34: =IF(OR(I34="",J34=""),"",INDEX('Datos maestros'!$B$153:$F$156,VALUE(LEFT(J34,1)),VALUE(LEFT(I34,1)))) -> Bajo | L34: Procedimientos operativos de TI y de la comunicación, Recomendaciones de seguridad | M34: Jefe de Producción | N34: =IF(A34="","",IF(COUNTIF('Tratamiento de riesgos'!$B:$B,A34)>0,"Sí","No")) -> No | O34: =IF(SUM(COUNTBLANK(B34:C34),COUNTBLANK(E34:F34),COUNTBLANK(I34:J34),COUNTBLANK(M34))>0,"⚠ Pendiente de completar","✓ Completo") -> ✓ Completo
A35: R31 | B35: Facturación electrónica PSE | C35: Accidental - técnico (falla de sistema/infraestructura) | D35: Tecnológico | E35: SignalR | F35: No existe autenticación en conexiones | G35: Acceso no autorizado | H35: Accesos no autorizado | I35: 3 - Serio | J35: 3 - Probable | K35: =IF(OR(I35="",J35=""),"",INDEX('Datos maestros'!$B$153:$F$156,VALUE(LEFT(J35,1)),VALUE(LEFT(I35,1)))) -> Medio | L35: Control de acceso | M35: Jefe de Desarrollo | N35: =IF(A35="","",IF(COUNTIF('Tratamiento de riesgos'!$B:$B,A35)>0,"Sí","No")) -> No | O35: =IF(SUM(COUNTBLANK(B35:C35),COUNTBLANK(E35:F35),COUNTBLANK(I35:J35),COUNTBLANK(M35))>0,"⚠ Pendiente de completar","✓ Completo") -> ✓ Completo
A36: R32 | B36: Facturación electrónica PSE | C36: Accidental - técnico (falla de sistema/infraestructura) | D36: Tecnológico | E36: Servidor virtual | F36: No hay protección DDOS en capa 7 en el ERP | G36: Ataque de Denegación de servicios | H36: Ataque cibernético | I36: 3 - Serio | J36: 3 - Probable | K36: =IF(OR(I36="",J36=""),"",INDEX('Datos maestros'!$B$153:$F$156,VALUE(LEFT(J36,1)),VALUE(LEFT(I36,1)))) -> Medio | L36: Reglas de firewall | M36: Jefe de Producción | N36: =IF(A36="","",IF(COUNTIF('Tratamiento de riesgos'!$B:$B,A36)>0,"Sí","No")) -> No | O36: =IF(SUM(COUNTBLANK(B36:C36),COUNTBLANK(E36:F36),COUNTBLANK(I36:J36),COUNTBLANK(M36))>0,"⚠ Pendiente de completar","✓ Completo") -> ✓ Completo
A37: R33 | B37: Facturación electrónica PSE | C37: Accidental - técnico (falla de sistema/infraestructura) | D37: Financiero | E37: Servicio - Visor web | F37: No controla las licencias en el lado del cliente | G37: Pérdida económica | H37: Pérdida económica | I37: 3 - Serio | J37: 3 - Probable | K37: =IF(OR(I37="",J37=""),"",INDEX('Datos maestros'!$B$153:$F$156,VALUE(LEFT(J37,1)),VALUE(LEFT(I37,1)))) -> Medio | L37: Control de acceso | M37: Jefe de Desarrollo | N37: =IF(A37="","",IF(COUNTIF('Tratamiento de riesgos'!$B:$B,A37)>0,"Sí","No")) -> No | O37: =IF(SUM(COUNTBLANK(B37:C37),COUNTBLANK(E37:F37),COUNTBLANK(I37:J37),COUNTBLANK(M37))>0,"⚠ Pendiente de completar","✓ Completo") -> ✓ Completo
A38: R34 | B38: Facturación electrónica PSE | C38: Accidental - técnico (falla de sistema/infraestructura) | D38: Financiero | E38: Sistema SIEMPRESOFT ERP (.exe) | F38: No se encuentra ofuscado | G38: Copia fraudulenta del proyecto (código fuente) | H38: Pérdida económica | I38: 4 - Crítico | J38: 2 – Bastante improbable | K38: =IF(OR(I38="",J38=""),"",INDEX('Datos maestros'!$B$153:$F$156,VALUE(LEFT(J38,1)),VALUE(LEFT(I38,1)))) -> Medio | L38: Control de acceso | M38: Jefe de Desarrollo | N38: =IF(A38="","",IF(COUNTIF('Tratamiento de riesgos'!$B:$B,A38)>0,"Sí","No")) -> No | O38: =IF(SUM(COUNTBLANK(B38:C38),COUNTBLANK(E38:F38),COUNTBLANK(I38:J38),COUNTBLANK(M38))>0,"⚠ Pendiente de completar","✓ Completo") -> ✓ Completo
A39: R35 | B39: Facturación electrónica PSE | C39: Accidental - técnico (falla de sistema/infraestructura) | D39: Reputacional | E39: Nombre del ambiente en el ERP | F39: Coincide con el nombre de la base de datos en Producción | G39: Ataque a la base de datos | H39: Mala reputación | I39: 4 - Crítico | J39: 3 - Probable | K39: =IF(OR(I39="",J39=""),"",INDEX('Datos maestros'!$B$153:$F$156,VALUE(LEFT(J39,1)),VALUE(LEFT(I39,1)))) -> Alto | L39: Control de acceso | M39: Jefe de Desarrollo | N39: =IF(A39="","",IF(COUNTIF('Tratamiento de riesgos'!$B:$B,A39)>0,"Sí","No")) -> Sí | O39: =IF(SUM(COUNTBLANK(B39:C39),COUNTBLANK(E39:F39),COUNTBLANK(I39:J39),COUNTBLANK(M39))>0,"⚠ Pendiente de completar","✓ Completo") -> ✓ Completo
A40: R36 | B40: Facturación electrónica PSE | C40: Accidental - técnico (falla de sistema/infraestructura) | D40: Operativo | E40: Dispositivos de punto final | F40: Sin licencia original del SO Windows | G40: Riesgo de infectarse de Botnet | H40: Ataque cibernético | I40: 2 - Significativo | J40: 1 - Improbable | K40: =IF(OR(I40="",J40=""),"",INDEX('Datos maestros'!$B$153:$F$156,VALUE(LEFT(J40,1)),VALUE(LEFT(I40,1)))) -> Muy bajo | L40: Política para los dispositivos BYOD | M40: Jefe de Producción | N40: =IF(A40="","",IF(COUNTIF('Tratamiento de riesgos'!$B:$B,A40)>0,"Sí","No")) -> No | O40: =IF(SUM(COUNTBLANK(B40:C40),COUNTBLANK(E40:F40),COUNTBLANK(I40:J40),COUNTBLANK(M40))>0,"⚠ Pendiente de completar","✓ Completo") -> ✓ Completo
...

Sheet Tratamiento de riesgos
A1: Tratamiento de Riesgos — SiempreSoft (vinculado por ID a la hoja "Matriz de riesgos")
A2: DOCUMENTO PARA: SGSI · ÁREA: SEGURIDAD DE LA INFORMACIÓN · NIVEL DE CONFIDENCIALIDAD: RESTRINGIDA · Subsana Obs.2 de auditoría (6.1.3): pestaña propia para el tratamiento, separada de identificación/análisis/evaluación y vinculada por ID
A3: Vínculo con Matriz de riesgos | E3: Plan de tratamiento | L3: Riesgo residual | O3: Cierre
A4: Item | B4: ID del riesgo | C4: Proceso (auto) | D4: Nivel de riesgo (auto) | E4: Opción de tratamiento | F4: Control / actividad a implementar | G4: Responsable de implementación | H4: Plazo inicio | I4: Plazo fin | J4: Recursos requeridos | K4: Estado de implementación | L4: Consecuencia residual | M4: Probabilidad residual | N4: Nivel de riesgo residual (auto) | O4: Fecha de cierre | P4: Observaciones
A5: 1 | B5: R06 | C5: =IFERROR(VLOOKUP(B5,'Matriz de riesgos'!$A:$B,2,0),"") -> Facturación electrónica PSE | D5: =IFERROR(VLOOKUP(B5,'Matriz de riesgos'!$A:$K,11,0),"") -> Alto | E5: 1. Elección de controles | F5: Implementar la identificación de usuario en aplicaciones con OpenID Connect para la autenticación en el ERP | G5: Jefe de Desarrollo | H5: Octubre 2024 | I5: Julio 2025 | J5: Humano Tecnológico | K5: Pendiente | N5: =IF(OR(L5="",M5=""),"",INDEX('Datos maestros'!$B$153:$F$156,VALUE(LEFT(M5,1)),VALUE(LEFT(L5,1))))
A6: 2 | B6: R16 | C6: =IFERROR(VLOOKUP(B6,'Matriz de riesgos'!$A:$B,2,0),"") -> Validación de comprobantes OSE | D6: =IFERROR(VLOOKUP(B6,'Matriz de riesgos'!$A:$K,11,0),"") -> Alto | E6: 1. Elección de controles | F6: Capacitación en las reglas WAF y revisiones periódicas de los registros y log | G6: Jefe de Producción | H6: Agosto 2023 | I6: Diciembre 2023 | J6: Humano | K6: Mitigado / Cerrado | N6: =IF(OR(L6="",M6=""),"",INDEX('Datos maestros'!$B$153:$F$156,VALUE(LEFT(M6,1)),VALUE(LEFT(L6,1)))) | P6: Inclusión en los procedimientos operativos de TI
A7: 3 | B7: R23 | C7: =IFERROR(VLOOKUP(B7,'Matriz de riesgos'!$A:$B,2,0),"") -> Validación de comprobantes OSE | D7: =IFERROR(VLOOKUP(B7,'Matriz de riesgos'!$A:$K,11,0),"") -> Alto | E7: 1. Elección de controles | F7: Seleccionar las tareas a automatizar y asignar los roles y responsables que deben verificar el cumplimiento | G7: Gerente general | H7: Agosto 2023 | I7: Octubre 2023 | J7: Humano Financiero | K7: Mitigado / Cerrado | N7: =IF(OR(L7="",M7=""),"",INDEX('Datos maestros'!$B$153:$F$156,VALUE(LEFT(M7,1)),VALUE(LEFT(L7,1)))) | P7: Actualización de procedimientos, creación de instructivos, capacitación
A8: 4 | B8: R28 | C8: =IFERROR(VLOOKUP(B8,'Matriz de riesgos'!$A:$B,2,0),"") -> Validación de comprobantes OSE | D8: =IFERROR(VLOOKUP(B8,'Matriz de riesgos'!$A:$K,11,0),"") -> Alto | E8: 1. Elección de controles | F8: Contratar el servicio HSM en la nube e implementar en Producción | G8: Gerente general | H8: Agosto 2023 | I8: Octubre 2023 | J8: Humano Tecnológico Financiero | K8: Mitigado / Cerrado | N8: =IF(OR(L8="",M8=""),"",INDEX('Datos maestros'!$B$153:$F$156,VALUE(LEFT(M8,1)),VALUE(LEFT(L8,1))))
A9: 5 | B9: R29 | C9: =IFERROR(VLOOKUP(B9,'Matriz de riesgos'!$A:$B,2,0),"") -> Facturación electrónica PSE | D9: =IFERROR(VLOOKUP(B9,'Matriz de riesgos'!$A:$K,11,0),"") -> Alto | E9: 1. Elección de controles | F9: Implementación del API PSE | G9: Jefe de Desarrollo | H9: Octubre 2023 | I9: Abril 2024 | J9: Humano Tecnológico | K9: Mitigado / Cerrado | N9: =IF(OR(L9="",M9=""),"",INDEX('Datos maestros'!$B$153:$F$156,VALUE(LEFT(M9,1)),VALUE(LEFT(L9,1)))) | P9: Pruebas en el API TEST
A10: 6 | B10: R35 | C10: =IFERROR(VLOOKUP(B10,'Matriz de riesgos'!$A:$B,2,0),"") -> Facturación electrónica PSE | D10: =IFERROR(VLOOKUP(B10,'Matriz de riesgos'!$A:$K,11,0),"") -> Alto | E10: 1. Elección de controles | F10: Cambio en código fuente | G10: Jefe de Desarrollo | H10: Enero 2025 | I10: Marzo 2025 | J10: Humano Tecnológico | K10: En tratamiento | N10: =IF(OR(L10="",M10=""),"",INDEX('Datos maestros'!$B$153:$F$156,VALUE(LEFT(M10,1)),VALUE(LEFT(L10,1)))) | P10: Elaborar propuesta a debatir Creación de BD múltiples con esquemas
A11: 7 | B11: R39 | C11: =IFERROR(VLOOKUP(B11,'Matriz de riesgos'!$A:$B,2,0),"") -> Ambos | D11: =IFERROR(VLOOKUP(B11,'Matriz de riesgos'!$A:$K,11,0),"") -> Alto | E11: 1. Elección de controles | F11: Planificación de beneficios sociales a los colaboradores | G11: Gerente general | H11: Abril 2024 | I11: Agosto 2024 | J11: Humano Financiero | K11: Mitigado / Cerrado | N11: =IF(OR(L11="",M11=""),"",INDEX('Datos maestros'!$B$153:$F$156,VALUE(LEFT(M11,1)),VALUE(LEFT(L11,1)))) | P11: - Fortalecimiento en la cultura organizacional, - Trabajo en equipo, - Sábados libres para todo el 2024 - Beneficios económicos de dividendos (trimestral)
A12: 8 | B12: R40 | C12: =IFERROR(VLOOKUP(B12,'Matriz de riesgos'!$A:$B,2,0),"") -> Ambos | D12: =IFERROR(VLOOKUP(B12,'Matriz de riesgos'!$A:$K,11,0),"") -> Alto | E12: 1. Elección de controles | F12: Configuración de proceso nocturnos en servidores virtuales | G12: Asistente de Producción | H12: Abril 2025 | J12: Humano | K12: Mitigado / Cerrado | N12: =IF(OR(L12="",M12=""),"",INDEX('Datos maestros'!$B$153:$F$156,VALUE(LEFT(M12,1)),VALUE(LEFT(L12,1)))) | P12: - Crear script para reconstruir indices - Crear tarea programada para mantenimiento de indices (notificaciones) - Programa de consola para la regularización en la uniformidad de los índices (ambos servidores) - Mejora en los índices (recomendaciones de portal azure y revisión de las consultas costosas del modelo hiperescala) - Antes de ejecutar la tarea cambiar al modelo de recuperacion Simple, cuando termiene el proceso se regresa al modelo de recuperación completa.
A13: 9 | B13: R42 | C13: =IFERROR(VLOOKUP(B13,'Matriz de riesgos'!$A:$B,2,0),"") -> Validación de comprobantes OSE | D13: =IFERROR(VLOOKUP(B13,'Matriz de riesgos'!$A:$K,11,0),"") -> Alto | E13: 1. Elección de controles | F13: Reporte de comprobantes enviados por cliente ERP y PSE | G13: Operador OSE | H13: Mayo 2025 | I13: Abril 2025 | J13: Humano | K13: Mitigado / Cerrado | N13: =IF(OR(L13="",M13=""),"",INDEX('Datos maestros'!$B$153:$F$156,VALUE(LEFT(M13,1)),VALUE(LEFT(L13,1)))) | P13: Elaboración de reporte. Envío de Reporte mensual al área de Administración (Operador OSE)
A14: 10 | B14: R43 | C14: =IFERROR(VLOOKUP(B14,'Matriz de riesgos'!$A:$B,2,0),"") -> Facturación electrónica PSE | D14: =IFERROR(VLOOKUP(B14,'Matriz de riesgos'!$A:$K,11,0),"") -> Alto | E14: 1. Elección de controles | F14: Migrar la versión del Framework ASP.NET a .NET Core | G14: Jefe de Desarrollo | H14: Mayo 2025 | I14: Abril 2026 | J14: Financiero Tecnológico Humano | K14: Pendiente | N14: =IF(OR(L14="",M14=""),"",INDEX('Datos maestros'!$B$153:$F$156,VALUE(LEFT(M14,1)),VALUE(LEFT(L14,1)))) | P14: Investigación por parte del área de Desarrollo Migrar parte del proyecto y realizar pruebas exhaustivas
A15: 11 | B15: R44 | C15: =IFERROR(VLOOKUP(B15,'Matriz de riesgos'!$A:$B,2,0),"") -> Validación de comprobantes OSE | D15: =IFERROR(VLOOKUP(B15,'Matriz de riesgos'!$A:$K,11,0),"") -> Alto | E15: 1. Elección de controles | F15: Mejora en las validaciones del OSE | G15: Desarrollador OSE | H15: Mayo 2025 | I15: Agosto 2025 | J15: Humano | K15: Mitigado / Cerrado | N15: =IF(OR(L15="",M15=""),"",INDEX('Datos maestros'!$B$153:$F$156,VALUE(LEFT(M15,1)),VALUE(LEFT(L15,1)))) | P15: Capturar observaciones de SUNAT en las constancias de recepción y acuse de recibo de los documentos.
A16: 12 | B16: R45 | C16: =IFERROR(VLOOKUP(B16,'Matriz de riesgos'!$A:$B,2,0),"") -> Validación de comprobantes OSE | D16: =IFERROR(VLOOKUP(B16,'Matriz de riesgos'!$A:$K,11,0),"") -> Alto | E16: 1. Elección de controles | F16: Elaboración de reporte de comprobantes rechazados | G16: Desarrollador OSE | H16: Mayo 2025 | I16: Agosto 2025 | J16: Humano | K16: Mitigado / Cerrado | N16: =IF(OR(L16="",M16=""),"",INDEX('Datos maestros'!$B$153:$F$156,VALUE(LEFT(M16,1)),VALUE(LEFT(L16,1)))) | P16: Elaboración de reporte. Envío de Reporte diario al área de Soporte al cliente
A17: 13 | B17: R46 | C17: =IFERROR(VLOOKUP(B17,'Matriz de riesgos'!$A:$B,2,0),"") -> Validación de comprobantes OSE | D17: =IFERROR(VLOOKUP(B17,'Matriz de riesgos'!$A:$K,11,0),"") -> Alto | E17: 1. Elección de controles | F17: Nuevo desarrollo para pruebas unitarias en el servicio OSE | G17: Desarrollador OSE | H17: Mayo 2025 | I17: Abril 2026 | J17: Tecnológico Humano | K17: Pendiente | N17: =IF(OR(L17="",M17=""),"",INDEX('Datos maestros'!$B$153:$F$156,VALUE(LEFT(M17,1)),VALUE(LEFT(L17,1)))) | P17: Nuevo desarrollo en DevOps y Pipeline
A18: 14 | B18: R48 | C18: =IFERROR(VLOOKUP(B18,'Matriz de riesgos'!$A:$B,2,0),"") -> Facturación electrónica PSE | D18: =IFERROR(VLOOKUP(B18,'Matriz de riesgos'!$A:$K,11,0),"") -> Alto | E18: 1. Elección de controles | F18: Nuevo flujo de despliegue en el ERP | G18: Jefe de Desarrollo | H18: Mayo 2025 | I18: Abril 2026 | J18: Tecnológico Humano | K18: Pendiente | N18: =IF(OR(L18="",M18=""),"",INDEX('Datos maestros'!$B$153:$F$156,VALUE(LEFT(M18,1)),VALUE(LEFT(L18,1)))) | P18: Nuevo desarrollo en DevOps y Pipeline
A19: 15 | B19: R49 | C19: =IFERROR(VLOOKUP(B19,'Matriz de riesgos'!$A:$B,2,0),"") -> Facturación electrónica PSE | D19: =IFERROR(VLOOKUP(B19,'Matriz de riesgos'!$A:$K,11,0),"") -> Alto | E19: 1. Elección de controles | F19: Mejora en el área de soporte al cliente | G19: Gerente general | H19: Mayo 2025 | I19: Setiembre 2025 | J19: Humano Financiero | K19: Mitigado / Cerrado | N19: =IF(OR(L19="",M19=""),"",INDEX('Datos maestros'!$B$153:$F$156,VALUE(LEFT(M19,1)),VALUE(LEFT(L19,1)))) | P19: Contratación de Analistas e Ingenieros de Soporte al cliente Retomar sábados libre Separación de área de Soporte (Help Desk y Ingeniería de Soporte al cliente)
A20: 16 | B20: R50 | C20: =IFERROR(VLOOKUP(B20,'Matriz de riesgos'!$A:$B,2,0),"") -> Ambos | D20: =IFERROR(VLOOKUP(B20,'Matriz de riesgos'!$A:$K,11,0),"") -> Medio | E20: 1. Elección de controles | F20: Creación de una web para el control de API | G20: Ingeniero I+D | H20: Mayo 2025 | I20: Setiembre 2025 | J20: Tecnológico Humano | K20: Mitigado / Cerrado | N20: =IF(OR(L20="",M20=""),"",INDEX('Datos maestros'!$B$153:$F$156,VALUE(LEFT(M20,1)),VALUE(LEFT(L20,1)))) | P20: Creación de una web para la administración de las API gestionadas por el área de Producción (nuevo menú en web Back Office)
A21: =IF(B21="","",ROW()-4) | C21: =IFERROR(VLOOKUP(B21,'Matriz de riesgos'!$A:$B,2,0),"") | D21: =IFERROR(VLOOKUP(B21,'Matriz de riesgos'!$A:$K,11,0),"") | N21: =IF(OR(L21="",M21=""),"",INDEX('Datos maestros'!$B$153:$F$156,VALUE(LEFT(M21,1)),VALUE(LEFT(L21,1))))
A22: =IF(B22="","",ROW()-4) | C22: =IFERROR(VLOOKUP(B22,'Matriz de riesgos'!$A:$B,2,0),"") | D22: =IFERROR(VLOOKUP(B22,'Matriz de riesgos'!$A:$K,11,0),"") | N22: =IF(OR(L22="",M22=""),"",INDEX('Datos maestros'!$B$153:$F$156,VALUE(LEFT(M22,1)),VALUE(LEFT(L22,1))))
A23: =IF(B23="","",ROW()-4) | C23: =IFERROR(VLOOKUP(B23,'Matriz de riesgos'!$A:$B,2,0),"") | D23: =IFERROR(VLOOKUP(B23,'Matriz de riesgos'!$A:$K,11,0),"") | N23: =IF(OR(L23="",M23=""),"",INDEX('Datos maestros'!$B$153:$F$156,VALUE(LEFT(M23,1)),VALUE(LEFT(L23,1))))
A24: =IF(B24="","",ROW()-4) | C24: =IFERROR(VLOOKUP(B24,'Matriz de riesgos'!$A:$B,2,0),"") | D24: =IFERROR(VLOOKUP(B24,'Matriz de riesgos'!$A:$K,11,0),"") | N24: =IF(OR(L24="",M24=""),"",INDEX('Datos maestros'!$B$153:$F$156,VALUE(LEFT(M24,1)),VALUE(LEFT(L24,1))))
A25: =IF(B25="","",ROW()-4) | C25: =IFERROR(VLOOKUP(B25,'Matriz de riesgos'!$A:$B,2,0),"") | D25: =IFERROR(VLOOKUP(B25,'Matriz de riesgos'!$A:$K,11,0),"") | N25: =IF(OR(L25="",M25=""),"",INDEX('Datos maestros'!$B$153:$F$156,VALUE(LEFT(M25,1)),VALUE(LEFT(L25,1))))
A26: =IF(B26="","",ROW()-4) | C26: =IFERROR(VLOOKUP(B26,'Matriz de riesgos'!$A:$B,2,0),"") | D26: =IFERROR(VLOOKUP(B26,'Matriz de riesgos'!$A:$K,11,0),"") | N26: =IF(OR(L26="",M26=""),"",INDEX('Datos maestros'!$B$153:$F$156,VALUE(LEFT(M26,1)),VALUE(LEFT(L26,1))))
A27: =IF(B27="","",ROW()-4) | C27: =IFERROR(VLOOKUP(B27,'Matriz de riesgos'!$A:$B,2,0),"") | D27: =IFERROR(VLOOKUP(B27,'Matriz de riesgos'!$A:$K,11,0),"") | N27: =IF(OR(L27="",M27=""),"",INDEX('Datos maestros'!$B$153:$F$156,VALUE(LEFT(M27,1)),VALUE(LEFT(L27,1))))
A28: =IF(B28="","",ROW()-4) | C28: =IFERROR(VLOOKUP(B28,'Matriz de riesgos'!$A:$B,2,0),"") | D28: =IFERROR(VLOOKUP(B28,'Matriz de riesgos'!$A:$K,11,0),"") | N28: =IF(OR(L28="",M28=""),"",INDEX('Datos maestros'!$B$153:$F$156,VALUE(LEFT(M28,1)),VALUE(LEFT(L28,1))))
A29: =IF(B29="","",ROW()-4) | C29: =IFERROR(VLOOKUP(B29,'Matriz de riesgos'!$A:$B,2,0),"") | D29: =IFERROR(VLOOKUP(B29,'Matriz de riesgos'!$A:$K,11,0),"") | N29: =IF(OR(L29="",M29=""),"",INDEX('Datos maestros'!$B$153:$F$156,VALUE(LEFT(M29,1)),VALUE(LEFT(L29,1))))
A30: =IF(B30="","",ROW()-4) | C30: =IFERROR(VLOOKUP(B30,'Matriz de riesgos'!$A:$B,2,0),"") | D30: =IFERROR(VLOOKUP(B30,'Matriz de riesgos'!$A:$K,11,0),"") | N30: =IF(OR(L30="",M30=""),"",INDEX('Datos maestros'!$B$153:$F$156,VALUE(LEFT(M30,1)),VALUE(LEFT(L30,1))))
A31: =IF(B31="","",ROW()-4) | C31: =IFERROR(VLOOKUP(B31,'Matriz de riesgos'!$A:$B,2,0),"") | D31: =IFERROR(VLOOKUP(B31,'Matriz de riesgos'!$A:$K,11,0),"") | N31: =IF(OR(L31="",M31=""),"",INDEX('Datos maestros'!$B$153:$F$156,VALUE(LEFT(M31,1)),VALUE(LEFT(L31,1))))
A32: =IF(B32="","",ROW()-4) | C32: =IFERROR(VLOOKUP(B32,'Matriz de riesgos'!$A:$B,2,0),"") | D32: =IFERROR(VLOOKUP(B32,'Matriz de riesgos'!$A:$K,11,0),"") | N32: =IF(OR(L32="",M32=""),"",INDEX('Datos maestros'!$B$153:$F$156,VALUE(LEFT(M32,1)),VALUE(LEFT(L32,1))))
... A50: =IF(B50="","",ROW()-4) | C50: =IFERROR(VLOOKUP(B50,'Matriz de riesgos'!$A:$B,2,0),"") | D50: =IFERROR(VLOOKUP(B50,'Matriz de riesgos'!$A:$K,11,0),"") | N50: =IF(OR(L50="",M50=""),"",INDEX('Datos maestros'!$B$153:$F$156,VALUE(LEFT(M50,1)),VALUE(LEFT(L50,1))))

Sheet Mapa de calor
A1: Mapa de calor de riesgos — conteo automático por Consecuencia × Probabilidad
A3: Se actualiza solo con COUNTIFS sobre la hoja "Matriz de riesgos". El número indica cuántos riesgos caen en esa celda.
B5: Consecuencia →
A6: Probabilidad ↓ | B6: 1 - Menor | C6: 2 - Significativo | D6: 3 - Serio | E6: 4 - Crítico | F6: 5 - Catastrófico
A7: 1 - Improbable | B7: =COUNTIFS('Matriz de riesgos'!$I$5:$I$80,"1 - Menor",'Matriz de riesgos'!$J$5:$J$80,"1 - Improbable") -> 0 | C7: =COUNTIFS('Matriz de riesgos'!$I$5:$I$80,"2 - Significativo",'Matriz de riesgos'!$J$5:$J$80,"1 - Improbable") -> 1 | D7: =COUNTIFS('Matriz de riesgos'!$I$5:$I$80,"3 - Serio",'Matriz de riesgos'!$J$5:$J$80,"1 - Improbable") -> 0 | E7: =COUNTIFS('Matriz de riesgos'!$I$5:$I$80,"4 - Crítico",'Matriz de riesgos'!$J$5:$J$80,"1 - Improbable") -> 2 | F7: =COUNTIFS('Matriz de riesgos'!$I$5:$I$80,"5 - Catastrófico",'Matriz de riesgos'!$J$5:$J$80,"1 - Improbable") -> 0
A8: 2 – Bastante improbable | B8: =COUNTIFS('Matriz de riesgos'!$I$5:$I$80,"1 - Menor",'Matriz de riesgos'!$J$5:$J$80,"2 – Bastante improbable") -> 0 | C8: =COUNTIFS('Matriz de riesgos'!$I$5:$I$80,"2 - Significativo",'Matriz de riesgos'!$J$5:$J$80,"2 – Bastante improbable") -> 0 | D8: =COUNTIFS('Matriz de riesgos'!$I$5:$I$80,"3 - Serio",'Matriz de riesgos'!$J$5:$J$80,"2 – Bastante improbable") -> 7 | E8: =COUNTIFS('Matriz de riesgos'!$I$5:$I$80,"4 - Crítico",'Matriz de riesgos'!$J$5:$J$80,"2 – Bastante improbable") -> 3 | F8: =COUNTIFS('Matriz de riesgos'!$I$5:$I$80,"5 - Catastrófico",'Matriz de riesgos'!$J$5:$J$80,"2 – Bastante improbable") -> 1
A9: 3 - Probable | B9: =COUNTIFS('Matriz de riesgos'!$I$5:$I$80,"1 - Menor",'Matriz de riesgos'!$J$5:$J$80,"3 - Probable") -> 0 | C9: =COUNTIFS('Matriz de riesgos'!$I$5:$I$80,"2 - Significativo",'Matriz de riesgos'!$J$5:$J$80,"3 - Probable") -> 7 | D9: =COUNTIFS('Matriz de riesgos'!$I$5:$I$80,"3 - Serio",'Matriz de riesgos'!$J$5:$J$80,"3 - Probable") -> 13 | E9: =COUNTIFS('Matriz de riesgos'!$I$5:$I$80,"4 - Crítico",'Matriz de riesgos'!$J$5:$J$80,"3 - Probable") -> 11 | F9: =COUNTIFS('Matriz de riesgos'!$I$5:$I$80,"5 - Catastrófico",'Matriz de riesgos'!$J$5:$J$80,"3 - Probable") -> 0
A10: 4 – Muy probable | B10: =COUNTIFS('Matriz de riesgos'!$I$5:$I$80,"1 - Menor",'Matriz de riesgos'!$J$5:$J$80,"4 – Muy probable") -> 0 | C10: =COUNTIFS('Matriz de riesgos'!$I$5:$I$80,"2 - Significativo",'Matriz de riesgos'!$J$5:$J$80,"4 – Muy probable") -> 1 | D10: =COUNTIFS('Matriz de riesgos'!$I$5:$I$80,"3 - Serio",'Matriz de riesgos'!$J$5:$J$80,"4 – Muy probable") -> 1 | E10: =COUNTIFS('Matriz de riesgos'!$I$5:$I$80,"4 - Crítico",'Matriz de riesgos'!$J$5:$J$80,"4 – Muy probable") -> 3 | F10: =COUNTIFS('Matriz de riesgos'!$I$5:$I$80,"5 - Catastrófico",'Matriz de riesgos'!$J$5:$J$80,"4 – Muy probable") -> 0
A13: Leyenda de nivel de riesgo
B14: Muy bajo
B15: Bajo
B16: Medio
B17: Alto
B18: Muy alto
A20: Totales por nivel
A21: Muy bajo | B21: =COUNTIF('Matriz de riesgos'!$K$5:$K$80,"Muy bajo") -> 1
A22: Bajo | B22: =COUNTIF('Matriz de riesgos'!$K$5:$K$80,"Bajo") -> 16
A23: Medio | B23: =COUNTIF('Matriz de riesgos'!$K$5:$K$80,"Medio") -> 18
A24: Alto | B24: =COUNTIF('Matriz de riesgos'!$K$5:$K$80,"Alto") -> 16
A25: Muy alto | B25: =COUNTIF('Matriz de riesgos'!$K$5:$K$80,"Muy alto") -> 0
A28: Totales por categoría de riesgo
A29: Estratégico | B29: =COUNTIF('Matriz de riesgos'!$D$5:$D$80,"Estratégico") -> 0
A30: Financiero | B30: =COUNTIF('Matriz de riesgos'!$D$5:$D$80,"Financiero") -> 9
A31: Operativo | B31: =COUNTIF('Matriz de riesgos'!$D$5:$D$80,"Operativo") -> 16
A32: Tecnológico | B32: =COUNTIF('Matriz de riesgos'!$D$5:$D$80,"Tecnológico") -> 18
A33: Legal / Normativo | B33: =COUNTIF('Matriz de riesgos'!$D$5:$D$80,"Legal / Normativo") -> 8
A34: Reputacional | B34: =COUNTIF('Matriz de riesgos'!$D$5:$D$80,"Reputacional") -> 6
A35: Político | B35: =COUNTIF('Matriz de riesgos'!$D$5:$D$80,"Político") -> 0
