Workbook

Sheet Guía y metodología
B2: Matriz de Identificación y Valoración de Riesgos
B3: SiempreSoft · Enfoque basado en eventos (ISO/IEC 27005:2022, Anexo A)
B5: 1. Dos ejes de clasificación: Origen vs. Categoría
B6: "Origen del riesgo" (Deliberado / Accidental-humano / Accidental-técnico / Ambiental) responde a QUIÉN o QUÉ dispara la amenaza — es la taxonomía de fuente de riesgo del Anexo A/B de ISO/IEC 27005:2022, que solo reconoce 3 orígenes (D/A/E, igual que tu hoja "Amenazas"): una falla técnica no es intencional ni ambiental, así que cae dentro de "Accidental" — aquí se subdivide en humano/técnico solo como ayuda operativa para saber qué tipo de control aplicar. "Categoría de riesgo" (Estratégico, Financiero, Operativo, Tecnológico, Legal/Normativo, Reputacional, Político) responde a EN QUÉ ÁMBITO DE NEGOCIO impacta — es la clasificación que usan COSO ERM / ISO 31000 para reportar a la dirección. Son ejes independientes: un mismo riesgo puede ser Origen=Deliberado + Categoría=Financiero (un estafador que busca beneficio económico), u Origen=Accidental-técnico + Categoría=Tecnológico (falla de Azure). Se agregó una columna nueva para cada eje en la hoja "Matriz de riesgos".
B8: 2. Catálogo de fuentes/amenazas por origen
B9: Las 8 categorías de fuente de riesgo deliberada (Relacionado a estados, Crimen organizado, Terrorista, Activista ideológico, Cibermercenario, Aficionado, Vengador, Agresor patológico) son el catálogo FIJO del Anexo A de ISO/IEC 27005:2022 — no es un límite que se haya impuesto, es la lista textual del estándar. Para los orígenes Accidental, Ambiental y Técnico existe otro catálogo, el de tipos de amenaza (Anexo B), que ya tenías cargado en tu hoja "Amenazas" con 72 entradas agrupadas en 7 tipos (física, eventos naturales, falla de infraestructura, fallas técnicas, acciones humanas, compromiso de funciones, amenazas organizacionales). En "Datos maestros" se agregó una tabla resumen de esos 7 tipos con ejemplos, que remite a tu catálogo completo para el detalle.
B11: 3. Matriz de nivel de riesgo (se mantiene 5×4)
B12: Se decidió mantener la matriz tal como la tienes (Consecuencia 5 niveles × Probabilidad 4 niveles), ya que la usan en otros documentos del SGSI. Nota para consistencia futura: si en algún momento migran a una matriz simétrica (5×5) o a un puntaje semicuantitativo, solo hay que actualizar la tabla H de "Datos maestros" — la fórmula de Nivel de riesgo en la matriz ya está preparada para leer de ahí sin tocar cada fila.
B14: 4. Qué cambia respecto a tu archivo original
B15: ● Fuente de riesgo vs. causa técnica
B16: En tu archivo, "Fuente de riesgo" mezclaba el agente (ej. "Organización criminal") con la causa técnica (ej. "Ausencia de pruebas en staging"). Se separó en "Origen del riesgo" (clasificado automáticamente, en cursiva gris — valídalo) y "Fuente de riesgo (causa u origen específico)" con tu texto original.
B17: ● DES solo aplica a orígenes deliberados
... B24: 5. Estructura del archivo
B25: Guía y metodología | C25: Esta hoja.
B26: Datos maestros | C26: Listas desplegables: procesos, origen del riesgo, categoría de riesgo, categorías de fuente deliberada (Anexo A), tipos de amenaza por origen A/E/T (Anexo B), motivaciones/DES, objetivos meta, escalas de consecuencia y probabilidad con criterios, matriz 5×4, propietarios, tratamiento y estados.
B27: Matriz de riesgos | C27: Identificación y valoración de los 56 riesgos existentes reorganizados + 20 filas en blanco. Nivel de riesgo y estado de completitud son fórmulas automáticas.
B28: Mapa de calor | C28: Conteo automático de riesgos por celda de la matriz 5×4, coloreado como heat map.
B30: 6. Leyenda de colores
C31: Celda pendiente de completar (dato que falta en tu archivo original o fila nueva).
C32: Celda calculada por fórmula — no editar a mano.
B33: Cursiva gris | C33: Origen o categoría sugeridos automáticamente a partir del texto original — valídalos.
B35: 7. Subsanación Obs.2 de auditoría (6.1.3 — pestaña de tratamiento separada y vinculada)
B36: El auditor observó que el tratamiento de riesgos debía ir en una pestaña propia, separada de la identificación/análisis/evaluación, y vinculada a ella. Se creó la hoja "Tratamiento de riesgos": cada fila referencia un ID de la "Matriz de riesgos" mediante un desplegable (no texto libre), y el Proceso y el Nivel de riesgo se traen automáticamente con VLOOKUP — si cambias la evaluación de un riesgo, su tratamiento se actualiza solo. En la "Matriz de riesgos" se retiraron las columnas de tratamiento (Opción, Estado, Observaciones) y se dejó una sola columna "¿Tiene tratamiento asignado?" que verifica contra la hoja nueva — se resalta en rojo cuando un riesgo Alto o Muy alto no tiene tratamiento registrado, para que puedas priorizar antes de la próxima auditoría. Se importaron los 16 tratamientos que ya tenías documentados (R06, R16, R23, R28, R29, R35, R39, R40, R42–R46, R48–R50); los de "Riesgos de Proyectos" (PY0x) no aplican a esta matriz y siguen en tu hoja original.

Sheet Datos maestros
A1: DATOS MAESTROS · listas desplegables y escalas de la matriz de riesgos
A3: A. Procesos
A4: Proceso
A5: Revisión por la Dirección
A6: Validación de comprobantes OSE
A7: Gestion Comercial
A8: Gestión del éxito y atención del cliente
A9: Ingenieria y calidad de sofware
A10: Gestion de operaciones
A11: Recursos humanos
A12: Facturación y cobranza
A13: Logística
... A17: B. Origen del riesgo (¿quién/qué lo origina? — Anexo A ISO/IEC 27005:2022)
A18: Origen | B18: Descripción
A19: Deliberado (humano intencional) | B19: Actor con intención consciente de causar daño u obtener beneficio (ciberdelincuentes, competidores, clientes hostiles, personal con intención maliciosa). Aquí sí aplica el DES / motivación.
A20: Accidental - humano (error no intencional) | B20: Subtipo de "Accidental" (código A del Anexo B). Error humano, falta de capacitación, procesos manuales, negligencia sin intención de dañar.
A21: Técnico (falla de sistema/infraestructura) | B21: Subtipo de "Accidental" (código A del Anexo B). El estándar no distingue un origen "Técnico" aparte: una falla de sistema no es intencional (no es D) ni viene del entorno físico (no es E), así que cae en Accidental. Se separa aquí solo como ayuda operativa, para diferenciar el control a aplicar (automatización/redundancia vs. capacitación/doble validación). Fallas de hardware/software, obsolescencia, configuración, capacidad, dependencia de terceros tecnológicos (ej. Azure).
A22: Ambiental | B22: Fenómenos naturales o climáticos: lluvias, inundaciones, sismos, descargas eléctricas. Código E del Anexo B.
A24: C. Categoría de riesgo (¿en qué ámbito de negocio impacta? — estilo COSO ERM / ISO 31000)
A25: Categoría | B25: Descripción
A26: Estratégico | B26: Afecta objetivos de negocio, crecimiento, mercado o modelo de negocio a mediano/largo plazo.
A27: Financiero | B27: Pérdida económica directa, costos, flujo de caja, cobranza, crédito, fraude con impacto monetario.
A28: Operativo | B28: Afecta la ejecución diaria de procesos: producción, soporte, calidad, capacidad, continuidad.
A29: Tecnológico | B29: Fallas o debilidades de sistemas, infraestructura, software, datos, ciberseguridad.
A30: Legal / Normativo | B30: Incumplimiento normativo, multas, sanciones, pérdida de autorización (SUNAT, PSE, OSE).
A31: Reputacional | B31: Daño a la imagen, confianza del cliente, quejas públicas, pérdida de credibilidad.
A32: Político | B32: Cambios regulatorios de origen gubernamental, relaciones con entidades públicas, entorno político/país.
A34: D. Categorías de fuente de riesgo DELIBERADA (catálogo fijo, Anexo A ISO/IEC 27005:2022)
A35: Categoría de fuente | B35: Actores típicos | C35: Método de ataque típico
A36: Relacionado a estados | B36: Estados, agencias de inteligencia | C36: Ataques dirigidos, profesionales, calendario predefinido (cadena de suministro).
A37: Crimen organizado | B37: Mafias, pandillas, organizaciones cibercriminales | C37: Estafas, ransomware, botnets, con fines lucrativos.
A38: Terrorista | B38: Ciber-terroristas, ciber-milicias | C38: Ataques poco sofisticados pero destructivos: denegación de servicio.
A39: Activista ideológico | B39: Ciber-hacktivistas, grupos de interés | C39: Similar al terrorista pero con intención menos destructiva (transmite una ideología).
A40: Cibermercenario | B40: Hackers especializados que crean kits/herramientas | C40: Diseño y venta de kits de ataque disponibles en línea.
A41: Aficionado | B41: Script-kiddies con buenos conocimientos informáticos | C41: Ataques básicos usando kits de ataque disponibles en línea.
A42: Vengador | B42: Ex-empleado, proveedor descontento | C42: Determinación y conocimiento interno de sistemas y procesos.
A43: Agresor patológico | B43: Competidor desleal, cliente deshonesto, estafador | C43: Base de conocimiento informático o subcontratación del ataque.
A45: E. Catálogo de amenazas para orígenes Accidental / Ambiental / Técnico (Anexo B ISO/IEC 27005:2022, tomado íntegro de tu hoja "Amenazas")
A46: A diferencia de "Deliberado" (que sí tiene su propio catálogo de actores en la tabla D, porque hay una intención humana caracterizable), el estándar NO define categorías de "fuente" separadas para Accidental/Ambiental/Técnico. En su lugar usa un catálogo único de amenazas (Anexo B), diferenciado por la columna Origen (D=deliberada, A=accidental, E=ambiental) — porque una misma amenaza puede tener más de un origen (ej. "Fuego" puede ser accidental, deliberado o ambiental a la vez). "Técnico" no es un código del estándar: es una subdivisión práctica que agregamos marcando en la columna ¿Técnico? las filas de los tipos "Fallas técnicas" y "Falla de infraestructura". Usa el autofiltro de Excel en esta tabla para quedarte solo con las filas que te interesan.
A48: Código | B48: Amenaza | C48: Tipo | D48: Origen (D/A/E) | E48: ¿Técnico?
...

Sheet Matriz de riesgos
A1: Matriz de Identificación y Valoración de Riesgos — SiempreSoft (enfoque basado en eventos)
A2: DOCUMENTO PARA: SGSI · ÁREA: SEGURIDAD DE LA INFORMACIÓN · NIVEL DE CONFIDENCIALIDAD: USO INTERNO · El tratamiento de riesgos se gestiona en la hoja "Tratamiento de riesgos" (vinculada por ID)
B3: Identificación del riesgo | M3: Evaluación del riesgo | R3: Seguimiento
A4: ID | B4: Proceso | C4: Origen del riesgo | D4: Categoría de riesgo | E4: Fuente de riesgo (causa u origen específico) | F4: Evento (que pasa tecnicamente) | G4: Estado final deseado / Motivación (DES) (solo si el origen es deliberado) | H4: Activo o proceso de negocio afectado | I4: Escenario estratégico (narrativa que conecta todo, sustenta consecuencia) | J4: Escenario operacional (que condición técnica hace que sea probable, sustenta probabilidad) | K4: Origen del hallazgo | L4: Referencia / evidencia | M4: Consecuencia | N4: Probabilidad | O4: Nivel de riesgo | P4: Controles existentes | Q4: Propietario del riesgo | R4: ¿Tiene tratamiento asignado? | S4: Estado del registro
A5: R46 | B5: Validación de comprobantes OSE | C5: Accidental - técnico (falla de sistema/infraestructura) | D5: Legal / Normativo | E5: Pruebas unitarias OSE | F5: Incumplimiento en la comprobación informática (reglas de validación no indicadas) | I5: Multas o sanciones | M5: 4 - Crítico | N5: 3 - Probable | O5: =IF(OR(M5="",N5=""),"",INDEX('Datos maestros'!$B$162:$F$165,VALUE(LEFT(N5,1)),VALUE(LEFT(M5,1)))) -> Alto | Q5: Desarrollador OSE | R5: =IF(A5="","",IF(COUNTIF('Tratamiento de riesgos'!$B:$B,A5)>0,"Sí","No")) -> Sí | S5: =IF(SUM(COUNTBLANK(B5:C5),COUNTBLANK(E5:F5),COUNTBLANK(M5:N5),COUNTBLANK(Q5))>0,"⚠ Pendiente de completar","✓ Completo") -> ✓ Completo
A6: R47 | B6: Gestión del éxito y atención del cliente | C6: Técnico (falla de sistema/infraestructura) | D6: Operativo | E6: Procesos manuales en la web de soporte: el cambio de estado, la notificación al cliente y el cierre de las solicitudes dependen de que el analista lo realice manualmente, sin reglas automáticas de cierre ni alertas de vencimiento. | F6: Solicitudes de soporte que permanecen abiertas o se cierran fuera de plazo, aun cuando ya fueron atendidas, por omisión u olvido del cierre manual o por falta de confirmación del cliente. | G6: No aplica | H6: Web de soporte al cliente Proceso de atención al cliente (SLA) Indicadores de atención al cliente | I6: Los tickets abiertos que ya fueron atendidos distorsionaba los indicadores de atención. | J6: El cierre de cada solicitus requiere de una acción manuao del Analista. No existen reglas de cierre automático por confirmación del cliente, ni alerta de tickets vencidos | K6: Revisión periódica | L6: Reportes de la web de soporte. | M6: 3 - Serio | N6: 3 - Probable | O6: =IF(OR(M6="",N6=""),"",INDEX('Datos maestros'!$B$162:$F$165,VALUE(LEFT(N6,1)),VALUE(LEFT(M6,1)))) -> Medio | P6: Revisión manual de los tickets | Q6: Jefe de Help Desk | R6: =IF(A6="","",IF(COUNTIF('Tratamiento de riesgos'!$B:$B,A6)>0,"Sí","No")) -> No | S6: =IF(SUM(COUNTBLANK(B6:C6),COUNTBLANK(E6:F6),COUNTBLANK(M6:N6),COUNTBLANK(Q6))>0,"⚠ Pendiente de completar","✓ Completo") -> ✓ Completo
A7: R48 | B7: Gestion de operaciones | C7: Técnico (falla de sistema/infraestructura) | D7: Operativo | E7: Ausencia de un entorno de staging que replique la configuración, los datos y las integraciones reales de producción (ERP/PSE); las pruebas se realizan solo en el entorno de desarrollo/QA, con datos y condiciones distintas a las reales. | F7: Despliegue en producción de versiones del ERP con errores no detectados en QA (fallas funcionales, de cálculo, de rendimiento o de integración), que se manifiestan recién cuando los clientes operan con la nueva versión. | G7: No aplica | H7: Versiones del ERP liberadas a producción · Proceso de despliegue y control de calidad | I7: Al liberar versiones sin validarlas en un entorno equivalente a producción, los errores llegan directamente a los clientes, afectando su operación diaria (ventas, emisión de comprobantes,contabilidad, reportes). Esto incrementa las quejas y solicitudes al área de soporte, obliga a correcciones urgentes (hotfix) o a revertir la versión, consume horas no planificadas de Desarrollo y Soporte, y deteriora la confianza del cliente en las actualizaciones del ERP. | J7: Las pruebas de QA se ejecutan en un entorno que no replica los volúmenes de datos, configuraciones particulares por cliente ni las integraciones reales. Sumado a la frecuencia de despliegues y a la ausencia de un pipeline de despliegue controlado (DevOps) con etapas de validación previas, es muy probable que errores propios del entorno real pasen a producción sin detectarse. | K7: Cambio (RFC) | L7: Tickets de soporte, quejas de clientes posteriores a despliegues de nuevas versiones; registros de hotfix o reversiones de versión. | M7: 4 - Crítico | N7: 4 – Muy probable | O7: =IF(OR(M7="",N7=""),"",INDEX('Datos maestros'!$B$162:$F$165,VALUE(LEFT(N7,1)),VALUE(LEFT(M7,1)))) -> Alto | P7: Recursos para pruebas de QA Procedimiento de control de calidad Procedimiento de reversión de versión | Q7: Jefe de Desarrollo | R7: =IF(A7="","",IF(COUNTIF('Tratamiento de riesgos'!$B:$B,A7)>0,"Sí","No")) -> Sí | S7: =IF(SUM(COUNTBLANK(B7:C7),COUNTBLANK(E7:F7),COUNTBLANK(M7:N7),COUNTBLANK(Q7))>0,"⚠ Pendiente de completar","✓ Completo") -> ✓ Completo
A8: R49 | B8: Gestión del éxito y atención del cliente | C8: Técnico (falla de sistema/infraestructura) | D8: Operativo | E8: Clientes insatisfechos por incidencias en el ERP/PSE, demoras en la solución o falta de respuesta oportuna, que canalizan su molestia mediante trato hostil hacia el personal de atención al cliente. | F8: Comportamiento agresivo de clientes (insultos, presión reiterada o trato irrespetuoso) por teléfono, WhatsApp o sesiones remotas hacia el personal de Help Desk y Soporte. | G8: No aplica | H8: Personal del área de atención al cliente (Help Desk e Ingeniería de Soporte) · Proceso de atención al cliente | I8: La exposición constante a clientes agresivos incrementa los niveles de estrés y desgaste emocional del personal de atención al cliente, provocando baja motivación. Esto genera errores en la atención, mayores tiempos de respuesta y deterioro de la calidad del servicio, lo que a su vez aumenta las quejas y afecta la imagen de la empresa. | J8: No se cuenta con un protocolo formal para el manejo de clientes agresivos ni con criterios de escalamiento hacia la jefatura; el personal atiende directamente y sin límites definidos. En periodos de alta demanda (cierres de mes, cambios normativos de SUNAT, fallas del servicio, despliegue de nuevas versiones) aumenta el volumen de solicitudes y la presión de los clientes, y no se registran los incidentes de trato hostil al personal. | K8: Otro | L8: Riesgo identificado por comentarios verbales del personal de Help Desk y Soporte a la jefatura. Los episodios de trato hostil no se registran formalmente a la fecha. | M8: 4 - Crítico | N8: 3 - Probable | O8: =IF(OR(M8="",N8=""),"",INDEX('Datos maestros'!$B$162:$F$165,VALUE(LEFT(N8,1)),VALUE(LEFT(M8,1)))) -> Alto | P8: Capacitación en atención al cliente Beneficios laborales para fidelizar el talento humano | Q8: Gerente general | R8: =IF(A8="","",IF(COUNTIF('Tratamiento de riesgos'!$B:$B,A8)>0,"Sí","No")) -> Sí | S8: =IF(SUM(COUNTBLANK(B8:C8),COUNTBLANK(E8:F8),COUNTBLANK(M8:N8),COUNTBLANK(Q8))>0,"⚠ Pendiente de completar","✓ Completo") -> ✓ Completo
A9: R50 | B9: Facturación y cobranza | C9: Accidental - humano (error no intencional) | D9: Financiero | E9: Debilidad en el análisis crediticio: no existe un procedimiento formal de evaluación de clientes antes de otorgar crédito o condiciones de pago diferido (sin criterios documentados de historial de pagos, consulta a centrales de riesgo, estados financieros ni límites de crédito aprobados). | F9: Aprobación de ventas, contratos o servicios al crédito a clientes cuya capacidad de pago no fue evaluada adecuadamente, generando cuentas por cobrar vencidas, morosidad prolongada o deudas incobrables. | G9: No aplica | H9: Proceso comercial y de otorgamiento de crédito · Cuentas por cobrar · Flujo de caja de la empresa | I9: Al otorgar crédito sin evaluar la solvencia del cliente, la empresa presta servicios (licencias ERP, PSE/OSE, implementación y soporte) que no son pagados en el plazo pactado o no llegan a recuperarse. Esto incrementa la cartera morosa, obliga a destinar recursos a gestiones de cobranza, afecta el flujo de caja y, ante la incobrabilidad, genera una pérdida económica directa por provisión o castigo de la deuda. | J9: La decisión de otorgar crédito depende del criterio individual del área de ventas, sin una evaluación previa estandarizada (consulta a centrales de riesgo, revisión del historial de pagos del cliente), sin límites de crédito por cliente y sin alertas de deuda vencida en el ERP. Por ello, clientes con alto riesgo de impago pueden ser aceptados sin detectarse oportunamente. | K9: Otro | L9: Reportes de Morosidad | M9: 3 - Serio | N9: 4 – Muy probable | O9: =IF(OR(M9="",N9=""),"",INDEX('Datos maestros'!$B$162:$F$165,VALUE(LEFT(N9,1)),VALUE(LEFT(M9,1)))) -> Alto | P9: Cpacitación en atención al cliente | Q9: Gerente general | R9: =IF(A9="","",IF(COUNTIF('Tratamiento de riesgos'!$B:$B,A9)>0,"Sí","No")) -> Sí | S9: =IF(SUM(COUNTBLANK(B9:C9),COUNTBLANK(E9:F9),COUNTBLANK(M9:N9),COUNTBLANK(Q9))>0,"⚠ Pendiente de completar","✓ Completo") -> ✓ Completo
A10: R51 | B10: Gestion de operaciones | C10: Técnico (falla de sistema/infraestructura) | D10: Tecnológico | E10: Credenciales (API key) de integraciones, gestionadas en un archivo Excel compartido como referencia, no cuenta con control de versiones ni gestión centralizada de secretos. | F10: Exposición de credenciales de API key almacenadas en archivo Excel, ante pérdida, filtración o acceso no controlado al archivo, al no existir rotación periódica ni trazabilidad de quién accede o modifica su contenido. | G10: No aplica | H10: Credenciales (API key) de integraciones del ERP · Archivo Excel de gestión de credenciales | I10: Si el archivo Excel llegara a circular fuera de su ámbito autorizado, las credenciales quedarían expuestas sin posibilidad de rotarlas de inmediato ni de saber desde cuándo estuvieron comprometidas. Esto habilitaría uso no autorizado de las integraciones del ERP y fuga de información. | J10: El cifrado automático de credenciales solo cubre el módulo de facturación electrónica; las credenciales de otras integraciones se documentan en un archivo Excel de uso interno sin un control centralizado de gestión de secretos. Adicionalmente, la rotación automática existente es anual y no genera alertas, por lo que un fallo en el proceso de rotación pasaría inadvertido. | K10: Otro | L10: Riesgo identificado por observación del proceso de despliegue: la gestión de credenciales en archivo Excel es realizada manualmente por el Asistente de Producción. Sin incidentes reportados a la fecha. | M10: 4 - Crítico | N10: 3 - Probable | O10: =IF(OR(M10="",N10=""),"",INDEX('Datos maestros'!$B$162:$F$165,VALUE(LEFT(N10,1)),VALUE(LEFT(M10,1)))) -> Alto | P10: Rotaciones automáticas anuales (sin alertas) Programa que cifra tag que contiene las credenciales (solo en el módulo de facturación electrónica) | Q10: Asistente de Producción | R10: =IF(A10="","",IF(COUNTIF('Tratamiento de riesgos'!$B:$B,A10)>0,"Sí","No")) -> Sí | S10: =IF(SUM(COUNTBLANK(B10:C10),COUNTBLANK(E10:F10),COUNTBLANK(M10:N10),COUNTBLANK(Q10))>0,"⚠ Pendiente de completar","✓ Completo") -> ✓ Completo
A11: R52 | B11: Gestión del éxito y atención del cliente | C11: Técnico (falla de sistema/infraestructura) | D11: Financiero | E11: Migración del código fuente del ERP a .NET Standard 2.0 con incompatibilidad de tipos de datos entre las versiones origen y destino. | F11: Cálculos inconsistentes en módulos críticos del ERP por incompatibilidad de tipos de datos tras la migración a .NET Standard. | G11: No aplica | H11: Módulos críticos del ERP (cálculos) · Código fuente migrado a .NET Standard | I11: La incompatibilidad de tipos de datos entre las versiones .NET produjo resultados de cálculo incorrectos en módulos críticos del ERP (promociones, bonificaciones, cantidad en los lotes), generando quejas de clientes al área de soporte al no coincidir los valores esperados con los obtenidos. | J11: La migración de código a .NET Standard implica cambios en el manejo interno de tipos de datos (precisión, redondeo, conversión implícita/explícita) que no siempre son equivalentes entre frameworks. Sin pruebas de regresión exhaustivas sobre los módulos de cálculo, estas diferencias pasan a producción sin detectarse. | K11: Cambio (RFC) | L11: Beta VF 5.22.17.1 VF 5.22.24.1 | M11: 4 - Crítico | N11: 2 – Bastante improbable | O11: =IF(OR(M11="",N11=""),"",INDEX('Datos maestros'!$B$162:$F$165,VALUE(LEFT(N11,1)),VALUE(LEFT(M11,1)))) -> Medio | P11: Procedimiento para el análisis de requerimiento Procedimiento de control de calidad Procedimiento de reversión de versión | Q11: Jefe de Desarrollo | R11: =IF(A11="","",IF(COUNTIF('Tratamiento de riesgos'!$B:$B,A11)>0,"Sí","No")) -> Sí | S11: =IF(SUM(COUNTBLANK(B11:C11),COUNTBLANK(E11:F11),COUNTBLANK(M11:N11),COUNTBLANK(Q11))>0,"⚠ Pendiente de completar","✓ Completo") -> ✓ Completo
A12: R53 | B12: Ingenieria y calidad de sofware | C12: Técnico (falla de sistema/infraestructura) | D12: Operativo | E12: Padrón interno de DNI (réplica de RENIEC en la base de datos del ERP) desactualizado: no incorporaba DNI de emisión reciente ni bajas por fallecimiento, y no existía mecanismo automático de actualización." | F12: Rechazo de guías de remisión por SUNAT al no poder validar el DNI del destinatario contra el padrón interno desactualizado. | G12: No aplica | H12: Padrón interno de DNI del ERP · Proceso de envios | I12: El rechazo del comprobante permitía corregir el DNI y reenviarlo a SUNAT, por lo que no se perdía el documento ni se incumplía la obligación tributaria. Sin embargo, cada rechazo obligaba a intervención manual del usuario y del área de soporte, distorsionaba los reportes de FE y generaba quejas de clientes por la fricción en su operación diaria. | J12: El padrón de DNI se mantenía como una réplica interna actualizada de forma periódica y manual, sin consulta en línea a RENIEC. Los DNI recientes o dado de baja por fallecimiento no era actualizado de manera inmediata, generando el rechazo y aumentando la cantidad de pendientes en el reporte diario. | K12: Revisión periódica | L12: Reportes de Facturación electrónica | M12: 3 - Serio | N12: 4 – Muy probable | O12: =IF(OR(M12="",N12=""),"",INDEX('Datos maestros'!$B$162:$F$165,VALUE(LEFT(N12,1)),VALUE(LEFT(M12,1)))) -> Alto | P12: Revisiones periódicas de facturación electrónica | Q12: Jefe de Desarrollo | R12: =IF(A12="","",IF(COUNTIF('Tratamiento de riesgos'!$B:$B,A12)>0,"Sí","No")) -> Sí | S12: =IF(SUM(COUNTBLANK(B12:C12),COUNTBLANK(E12:F12),COUNTBLANK(M12:N12),COUNTBLANK(Q12))>0,"⚠ Pendiente de completar","✓ Completo") -> ✓ Completo
A13: R54 | B13: Ingenieria y calidad de sofware | C13: Accidental - humano (error no intencional) | D13: Legal / Normativo | E13: Uso de herramientas públicas de Inteligencia Artificial durante actividades de análisis, depuración o soporte técnico. | F13: Carga o exposición de fragmentos de código fuente, consultas SQL, cadenas de conexión o fuga de datos del ERP en plataformas públicas de Inteligencia Artificial. | G13: No aplica | H13: Código fuente del ERP, Bases de datos, Propiedad intelectual | I13: Durante actividades de soporte, análisis o depuración de incidencias, podría existir la necesidad de utilizar herramientas públicas de Inteligencia Artificial como apoyo técnico. En caso de no aplicarse criterios adecuados de clasificación y protección de la información, existe la posibilidad de que información técnica de la organización sea expuesta fuera de los entornos controlados por Siempresoft. | J13: La creciente disponibilidad y facilidad de acceso a herramientas de Inteligencia Artificial incrementa la probabilidad de que estas sean utilizadas durante tareas de desarrollo o soporte, si bien existen controles administrativos no se cuenta con controles técnicos que validen el tipo de información compartida. | K13: Otro | L13: Riesgo emergente identificado en revisión del SGSI 2026. Sin incidentes reportados a la fecha. | M13: 4 - Crítico | N13: 3 - Probable | O13: =IF(OR(M13="",N13=""),"",INDEX('Datos maestros'!$B$162:$F$165,VALUE(LEFT(N13,1)),VALUE(LEFT(M13,1)))) -> Alto | P13: Directivas de etiquetado - Microsoft Purview Compromiso de no divulgación Declaración de no divulgación Capacitaciones de concientización | Q13: Jefe de Producción | R13: =IF(A13="","",IF(COUNTIF('Tratamiento de riesgos'!$B:$B,A13)>0,"Sí","No")) -> Sí | S13: =IF(SUM(COUNTBLANK(B13:C13),COUNTBLANK(E13:F13),COUNTBLANK(M13:N13),COUNTBLANK(Q13))>0,"⚠ Pendiente de completar","✓ Completo") -> ✓ Completo
A14: R55 | B14: Gestion de operaciones | C14: Técnico (falla de sistema/infraestructura) | D14: Tecnológico | E14: Cambios/mantenimiento de infraestructura del proveedor cloud | F14: Pérdida parcial de conectividad entre una máquina virtual y los servicios publicados debido a problemas de enrutamiento de red en la región West US. | G14: No aplica | H14: Servicios del ERP alojados en el servidor de Azure | I14: Una degradación de conectividad en la región West US afectó únicamente a uno de los servidores de producción (10.0.0.7), impidiendo la llamada a los servicios del IIS. La demora en la publicación de información oficial por parte de Azure provocó que el equipo técnico dedicara un tiempo considerable a actividades de diagnóstico e investigación, retrasando la restauración normal del servicio y afectando la capacidad de respuesta ante el incidente. | J14: La organización depende de servicios de red administrados por Azure y no tiene visibilidad directa sobre los cambios internos de infraestructura del proveedor. Debido a que la incidencia afectó únicamente determinados flujos de red y no todos los servicios del servidor (BD operativas), el diagnóstico inicial fue complejo y generó múltiples actividades de análisis antes de identificar la causa real del incidente. | K14: Incidente de seguridad | L14: RISI_01_2026 | M14: 4 - Crítico | N14: 3 - Probable | O14: =IF(OR(M14="",N14=""),"",INDEX('Datos maestros'!$B$162:$F$165,VALUE(LEFT(N14,1)),VALUE(LEFT(M14,1)))) -> Alto | P14: Alertas de Azure Services Health Solicitud de soporte de Azure Aporte de investigación en la IA | Q14: Jefe de Producción | R14: =IF(A14="","",IF(COUNTIF('Tratamiento de riesgos'!$B:$B,A14)>0,"Sí","No")) -> Sí | S14: =IF(SUM(COUNTBLANK(B14:C14),COUNTBLANK(E14:F14),COUNTBLANK(M14:N14),COUNTBLANK(Q14))>0,"⚠ Pendiente de completar","✓ Completo") -> ✓ Completo
A15: R56 | B15: Gestión del éxito y atención del cliente | C15: Técnico (falla de sistema/infraestructura) | D15: Operativo | E15: Cambios en servicios o políticas de proveedores cloud. | F15: Los usuarios invitados externos ya no pueden acceder directamente a videos compartidos debido a nuevas validaciones de identidad requeridas por Microsoft Entra ID (B2B). | G15: No aplica | H15: Capacitación a clientes | I15: La modificación de las directivas de seguridad para usuarios invitados impide que clientes accedan directamente al material de capacitación compartido, esto genera retrasos en la transferencia de conocimiento, incrementa las solicitudes de soporte. La solución indicada por el proveedor (incorporar al cliente como invitado en el tenant de Microsoft Entra ID) fue evaluada y descartada por SiempreSoft por riesgo de exposición del tenant, por lo que el flujo actual de distribución seguirá bloqueado mientras no se defina un canal alternativo. | J15: Los videos de capacitación fueron compartidos utilizando usuarios invitados sin un procedimiento formal de incorporación al tenant de Microsoft Entra ID. Ante cambios futuros en las políticas de acceso, los usuarios deberán ser registrados, invitados y aceptar previamente la invitación para acceder al contenido. | K15: Cambio (RFC) | L15: TrackingID#2608140040005948 GRABACIONES DE CAPACITACIONES / DEMOSTRACIONES - SIEMPRESOFT (15/9/26) | M15: 2 - Significativo | N15: 3 - Probable | O15: =IF(OR(M15="",N15=""),"",INDEX('Datos maestros'!$B$162:$F$165,VALUE(LEFT(N15,1)),VALUE(LEFT(M15,1)))) -> Bajo | P15: Creación de tickets de soporte | Q15: Jefe de Producción | R15: =IF(A15="","",IF(COUNTIF('Tratamiento de riesgos'!$B:$B,A15)>0,"Sí","No")) -> No | S15: =IF(SUM(COUNTBLANK(B15:C15),COUNTBLANK(E15:F15),COUNTBLANK(M15:N15),COUNTBLANK(Q15))>0,"⚠ Pendiente de completar","✓ Completo") -> ✓ Completo
A16: R57 | B16: Infraestructura tecnológica | C16: Técnico (falla de sistema/infraestructura) | D16: Tecnológico | E16: Actualización acumulativa defectuosa de Windows Server 2022 publicada por Microsoft sin pruebas suficientes y no retirada del canal de distribución pese a haber sido detectada, aplicada automáticamente en VM nuevas de Azure. | F16: Bloqueo del protocolo de escritorio remoto (RDP) en servidor de Producción tras la actualización provoca pérdida de acceso | G16: No aplica | H16: Servidor nuevo (Windows Server 2022) destinado al ERP | I16: Se aplica una actualización acumulativa del SO → el servicio RDP del servidor de Producción queda bloqueado → se pierde el acceso administrativo a la VM → se interrumpe la disponibilidad de acceso para copiar los binarios a instalar. | J16: Los servidores de producción no cuentan con ventana de pruebas/staging previa a la aplicación de actualizaciones del SO, ni con snapshot/rollback automático — cualquier actualización acumulativa se despliega directo a producción sin validar compatibilidad con los servicios y/o aplicaciones. | K16: Incidente de seguridad | L16: RISI_03_2026 | M16: 4 - Crítico | N16: 4 – Muy probable | O16: =IF(OR(M16="",N16=""),"",INDEX('Datos maestros'!$B$162:$F$165,VALUE(LEFT(N16,1)),VALUE(LEFT(M16,1)))) -> Alto | P16: Procedimientos Operativos para TI y de la Comunicación / Actualizaciones previas de SO en servidor de pruebas QA Solicitud de soporte de Azure | Q16: Jefe de Producción | R16: =IF(A16="","",IF(COUNTIF('Tratamiento de riesgos'!$B:$B,A16)>0,"Sí","No")) -> Sí | S16: =IF(SUM(COUNTBLANK(B16:C16),COUNTBLANK(E16:F16),COUNTBLANK(M16:N16),COUNTBLANK(Q16))>0,"⚠ Pendiente de completar","✓ Completo") -> ✓ Completo
A17: R58 | B17: Ingenieria y calidad de sofware | C17: Técnico (falla de sistema/infraestructura) | D17: Operativo | E17: Actualización del ERP desde una versión acumulada sin validación completa de compatibilidad funcional. | F17: Errores de cálculo en el manejo de lotes que impiden registrar ventas al cliente OP | G17: No aplica | H17: Proceso de ventas en cliente OP | I17: La actualización del ERP generó inconsistencias en el manejo de lotes, impidiendo registrar correctamente las ventas en las cajas. Como consecuencia, las operaciones comerciales del cliente se interrumpieron temporalmente, generando pérdida de productividad, retrasos operativos y reclamos hacia Siempresoft. | J17: Las nuevas versiones pasan por el flujo completo de pruebas y por un periodo de estabilización de dos semanas en el entorno SaaS antes de instalarse en clientes On-Premise. Sin embargo, la validación no cubre la configuración ni los datos específicos de cada cliente OP, que además parten de un desfase acumulado de versiones respecto a la versión estable. Esa combinación no está cubierta por las pruebas de regresión actuales. | K17: Incidente de seguridad | L17: RISI_04_2026 | M17: 4 - Crítico | N17: 2 – Bastante improbable | O17: =IF(OR(M17="",N17=""),"",INDEX('Datos maestros'!$B$162:$F$165,VALUE(LEFT(N17,1)),VALUE(LEFT(M17,1)))) -> Medio | P17: Procedimiento de despliegue de nueva versión del ERP Pruebas de control de calidad Procedimiento de reversión de instalación del ERP | Q17: Jefe de Desarrollo | R17: =IF(A17="","",IF(COUNTIF('Tratamiento de riesgos'!$B:$B,A17)>0,"Sí","No")) -> No | S17: =IF(SUM(COUNTBLANK(B17:C17),COUNTBLANK(E17:F17),COUNTBLANK(M17:N17),COUNTBLANK(Q17))>0,"⚠ Pendiente de completar","✓ Completo") -> ✓ Completo
A18: R59 | O18: =IF(OR(M18="",N18=""),"",INDEX('Datos maestros'!$B$162:$F$165,VALUE(LEFT(N18,1)),VALUE(LEFT(M18,1))))
A19: R60 | O19: =IF(OR(M19="",N19=""),"",INDEX('Datos maestros'!$B$162:$F$165,VALUE(LEFT(N19,1)),VALUE(LEFT(M19,1))))
A20: R61 | O20: =IF(OR(M20="",N20=""),"",INDEX('Datos maestros'!$B$162:$F$165,VALUE(LEFT(N20,1)),VALUE(LEFT(M20,1))))
A21: R62 | O21: =IF(OR(M21="",N21=""),"",INDEX('Datos maestros'!$B$162:$F$165,VALUE(LEFT(N21,1)),VALUE(LEFT(M21,1))))
A22: R63 | O22: =IF(OR(M22="",N22=""),"",INDEX('Datos maestros'!$B$162:$F$165,VALUE(LEFT(N22,1)),VALUE(LEFT(M22,1))))
A23: R64 | O23: =IF(OR(M23="",N23=""),"",INDEX('Datos maestros'!$B$162:$F$165,VALUE(LEFT(N23,1)),VALUE(LEFT(M23,1))))
A24: R65
A25: R66 | O25: =IF(OR(M25="",N25=""),"",INDEX('Datos maestros'!$B$162:$F$165,VALUE(LEFT(N25,1)),VALUE(LEFT(M25,1))))
A26: R67 | O26: =IF(OR(M26="",N26=""),"",INDEX('Datos maestros'!$B$162:$F$165,VALUE(LEFT(N26,1)),VALUE(LEFT(M26,1))))
A27: R68 | O27: =IF(OR(M27="",N27=""),"",INDEX('Datos maestros'!$B$162:$F$165,VALUE(LEFT(N27,1)),VALUE(LEFT(M27,1))))
A28: R69 | O28: =IF(OR(M28="",N28=""),"",INDEX('Datos maestros'!$B$162:$F$165,VALUE(LEFT(N28,1)),VALUE(LEFT(M28,1))))
A29: R70 | O29: =IF(OR(M29="",N29=""),"",INDEX('Datos maestros'!$B$162:$F$165,VALUE(LEFT(N29,1)),VALUE(LEFT(M29,1))))
A30: R71 | O30: =IF(OR(M30="",N30=""),"",INDEX('Datos maestros'!$B$162:$F$165,VALUE(LEFT(N30,1)),VALUE(LEFT(M30,1))))
A31: R72 | O31: =IF(OR(M31="",N31=""),"",INDEX('Datos maestros'!$B$162:$F$165,VALUE(LEFT(N31,1)),VALUE(LEFT(M31,1))))
A32: R73 | O32: =IF(OR(M32="",N32=""),"",INDEX('Datos maestros'!$B$162:$F$165,VALUE(LEFT(N32,1)),VALUE(LEFT(M32,1))))
A33: R74 | O33: =IF(OR(M33="",N33=""),"",INDEX('Datos maestros'!$B$162:$F$165,VALUE(LEFT(N33,1)),VALUE(LEFT(M33,1))))
A34: R75 | O34: =IF(OR(M34="",N34=""),"",INDEX('Datos maestros'!$B$162:$F$165,VALUE(LEFT(N34,1)),VALUE(LEFT(M34,1))))
A35: R76 | O35: =IF(OR(M35="",N35=""),"",INDEX('Datos maestros'!$B$162:$F$165,VALUE(LEFT(N35,1)),VALUE(LEFT(M35,1))))

Sheet Mapa de calor
A1: Mapa de calor de riesgos — conteo automático por Consecuencia × Probabilidad
A3: Se actualiza solo con COUNTIFS sobre la hoja "Matriz de riesgos". El número indica cuántos riesgos caen en esa celda.
B5: Consecuencia →
A6: Probabilidad ↓ | B6: 1 - Menor | C6: 2 - Significativo | D6: 3 - Serio | E6: 4 - Crítico | F6: 5 - Catastrófico
A7: 1 - Improbable | B7: =COUNTIFS('Matriz de riesgos'!$M$5:$M$35,"1 - Menor",'Matriz de riesgos'!$N$5:$N$35,"1 - Improbable") -> 0 | C7: =COUNTIFS('Matriz de riesgos'!$M$5:$M$35,"2 - Significativo",'Matriz de riesgos'!$N$5:$N$35,"1 - Improbable") -> 0 | D7: =COUNTIFS('Matriz de riesgos'!$M$5:$M$35,"3 - Serio",'Matriz de riesgos'!$N$5:$N$35,"1 - Improbable") -> 0 | E7: =COUNTIFS('Matriz de riesgos'!$M$5:$M$35,"4 - Crítico",'Matriz de riesgos'!$N$5:$N$35,"1 - Improbable") -> 0 | F7: =COUNTIFS('Matriz de riesgos'!$M$5:$M$35,"5 - Catastrófico",'Matriz de riesgos'!$N$5:$N$35,"1 - Improbable") -> 0
A8: 2 – Bastante improbable | B8: =COUNTIFS('Matriz de riesgos'!$M$5:$M$35,"1 - Menor",'Matriz de riesgos'!$N$5:$N$35,"2 – Bastante improbable") -> 0 | C8: =COUNTIFS('Matriz de riesgos'!$M$5:$M$35,"2 - Significativo",'Matriz de riesgos'!$N$5:$N$35,"2 – Bastante improbable") -> 0 | D8: =COUNTIFS('Matriz de riesgos'!$M$5:$M$35,"3 - Serio",'Matriz de riesgos'!$N$5:$N$35,"2 – Bastante improbable") -> 0 | E8: =COUNTIFS('Matriz de riesgos'!$M$5:$M$35,"4 - Crítico",'Matriz de riesgos'!$N$5:$N$35,"2 – Bastante improbable") -> 2 | F8: =COUNTIFS('Matriz de riesgos'!$M$5:$M$35,"5 - Catastrófico",'Matriz de riesgos'!$N$5:$N$35,"2 – Bastante improbable") -> 0
A9: 3 - Probable | B9: =COUNTIFS('Matriz de riesgos'!$M$5:$M$35,"1 - Menor",'Matriz de riesgos'!$N$5:$N$35,"3 - Probable") -> 0 | C9: =COUNTIFS('Matriz de riesgos'!$M$5:$M$35,"2 - Significativo",'Matriz de riesgos'!$N$5:$N$35,"3 - Probable") -> 1 | D9: =COUNTIFS('Matriz de riesgos'!$M$5:$M$35,"3 - Serio",'Matriz de riesgos'!$N$5:$N$35,"3 - Probable") -> 1 | E9: =COUNTIFS('Matriz de riesgos'!$M$5:$M$35,"4 - Crítico",'Matriz de riesgos'!$N$5:$N$35,"3 - Probable") -> 5 | F9: =COUNTIFS('Matriz de riesgos'!$M$5:$M$35,"5 - Catastrófico",'Matriz de riesgos'!$N$5:$N$35,"3 - Probable") -> 0
A10: 4 – Muy probable | B10: =COUNTIFS('Matriz de riesgos'!$M$5:$M$35,"1 - Menor",'Matriz de riesgos'!$N$5:$N$35,"4 – Muy probable") -> 0 | C10: =COUNTIFS('Matriz de riesgos'!$M$5:$M$35,"2 - Significativo",'Matriz de riesgos'!$N$5:$N$35,"4 – Muy probable") -> 0 | D10: =COUNTIFS('Matriz de riesgos'!$M$5:$M$35,"3 - Serio",'Matriz de riesgos'!$N$5:$N$35,"4 – Muy probable") -> 2 | E10: =COUNTIFS('Matriz de riesgos'!$M$5:$M$35,"4 - Crítico",'Matriz de riesgos'!$N$5:$N$35,"4 – Muy probable") -> 2 | F10: =COUNTIFS('Matriz de riesgos'!$M$5:$M$35,"5 - Catastrófico",'Matriz de riesgos'!$N$5:$N$35,"4 – Muy probable") -> 0
A13: Leyenda de nivel de riesgo
B14: Muy bajo
B15: Bajo
B16: Medio
B17: Alto
B18: Muy alto
A20: Totales por nivel
A21: Muy bajo | B21: =COUNTIF('Matriz de riesgos'!$O$5:$O$35,"Muy bajo") -> 0
A22: Bajo | B22: =COUNTIF('Matriz de riesgos'!$O$5:$O$35,"Bajo") -> 1
A23: Medio | B23: =COUNTIF('Matriz de riesgos'!$O$5:$O$35,"Medio") -> 3
A24: Alto | B24: =COUNTIF('Matriz de riesgos'!$O$5:$O$35,"Alto") -> 9
A25: Muy alto | B25: =COUNTIF('Matriz de riesgos'!$O$5:$O$35,"Muy alto") -> 0
A28: Totales por categoría de riesgo
A29: Estratégico | B29: =COUNTIF('Matriz de riesgos'!$D$5:$D$35,"Estratégico") -> 0
A30: Financiero | B30: =COUNTIF('Matriz de riesgos'!$D$5:$D$35,"Financiero") -> 2
A31: Operativo | B31: =COUNTIF('Matriz de riesgos'!$D$5:$D$35,"Operativo") -> 6
A32: Tecnológico | B32: =COUNTIF('Matriz de riesgos'!$D$5:$D$35,"Tecnológico") -> 3
A33: Legal / Normativo | B33: =COUNTIF('Matriz de riesgos'!$D$5:$D$35,"Legal / Normativo") -> 2
A34: Reputacional | B34: =COUNTIF('Matriz de riesgos'!$D$5:$D$35,"Reputacional") -> 0
A35: Político | B35: =COUNTIF('Matriz de riesgos'!$D$5:$D$35,"Político") -> 0

Sheet Tratamiento de riesgos
A1: Tratamiento de Riesgos — SiempreSoft (vinculado por ID a la hoja "Matriz de riesgos")
A2: DOCUMENTO PARA: SGSI · ÁREA: SEGURIDAD DE LA INFORMACIÓN · NIVEL DE CONFIDENCIALIDAD: RESTRINGIDA · Subsana Obs.2 de auditoría (6.1.3): pestaña propia para el tratamiento, separada de identificación/análisis/evaluación y vinculada por ID
A3: Vínculo con Matriz de riesgos | E3: Plan de tratamiento | L3: Riesgo residual | O3: Cierre
A4: Item | B4: ID del riesgo | C4: Proceso (auto) | D4: Nivel de riesgo (auto) | E4: Opción de tratamiento | F4: Control / actividad a implementar | G4: Responsable de implementación | H4: Plazo inicio | I4: Plazo fin | J4: Recursos requeridos | K4: Estado de implementación | L4: Consecuencia residual | M4: Probabilidad residual | N4: Nivel de riesgo residual (auto) | O4: Fecha de cierre | P4: Observaciones
A5: 1 | B5: R06 | C5: =IFERROR(VLOOKUP(B5,'Matriz de riesgos'!$A:$B,2,0),"") | D5: =IFERROR(VLOOKUP(B5,'Matriz de riesgos'!$A:$O,15,0),"") | E5: 1. Elección de controles | F5: Implementar la identificación de usuario en aplicaciones con OpenID Connect para la autenticación en el ERP | G5: Jefe de Desarrollo | H5: Octubre 2024 | I5: Julio 2025 | J5: Humano Tecnológico | K5: Pendiente | N5: =IF(OR(L5="",M5=""),"",INDEX('Datos maestros'!$B$162:$F$165,VALUE(LEFT(M5,1)),VALUE(LEFT(L5,1))))
A6: 2 | B6: R16 | C6: =IFERROR(VLOOKUP(B6,'Matriz de riesgos'!$A:$B,2,0),"") | D6: =IFERROR(VLOOKUP(B6,'Matriz de riesgos'!$A:$O,15,0),"") | E6: 1. Elección de controles | F6: Capacitación en las reglas WAF y revisiones periódicas de los registros y log | G6: Jefe de Producción | H6: Agosto 2023 | I6: Diciembre 2023 | J6: Humano | K6: Mitigado / Cerrado | N6: =IF(OR(L6="",M6=""),"",INDEX('Datos maestros'!$B$162:$F$165,VALUE(LEFT(M6,1)),VALUE(LEFT(L6,1)))) | P6: Inclusión en los procedimientos operativos de TI
A7: 3 | B7: R23 | C7: =IFERROR(VLOOKUP(B7,'Matriz de riesgos'!$A:$B,2,0),"") | D7: =IFERROR(VLOOKUP(B7,'Matriz de riesgos'!$A:$O,15,0),"") | E7: 1. Elección de controles | F7: Seleccionar las tareas a automatizar y asignar los roles y responsables que deben verificar el cumplimiento | G7: Gerente general | H7: Agosto 2023 | I7: Octubre 2023 | J7: Humano Financiero | K7: Mitigado / Cerrado | N7: =IF(OR(L7="",M7=""),"",INDEX('Datos maestros'!$B$162:$F$165,VALUE(LEFT(M7,1)),VALUE(LEFT(L7,1)))) | P7: Actualización de procedimientos, creación de instructivos, capacitación
A8: 4 | B8: R28 | C8: =IFERROR(VLOOKUP(B8,'Matriz de riesgos'!$A:$B,2,0),"") | D8: =IFERROR(VLOOKUP(B8,'Matriz de riesgos'!$A:$O,15,0),"") | E8: 1. Elección de controles | F8: Contratar el servicio HSM en la nube e implementar en Producción | G8: Gerente general | H8: Agosto 2023 | I8: Octubre 2023 | J8: Humano Tecnológico Financiero | K8: Mitigado / Cerrado | N8: =IF(OR(L8="",M8=""),"",INDEX('Datos maestros'!$B$162:$F$165,VALUE(LEFT(M8,1)),VALUE(LEFT(L8,1))))
A9: 5 | B9: R29 | C9: =IFERROR(VLOOKUP(B9,'Matriz de riesgos'!$A:$B,2,0),"") | D9: =IFERROR(VLOOKUP(B9,'Matriz de riesgos'!$A:$O,15,0),"") | E9: 1. Elección de controles | F9: Implementación del API PSE | G9: Jefe de Desarrollo | H9: Octubre 2023 | I9: Abril 2024 | J9: Humano Tecnológico | K9: Mitigado / Cerrado | N9: =IF(OR(L9="",M9=""),"",INDEX('Datos maestros'!$B$162:$F$165,VALUE(LEFT(M9,1)),VALUE(LEFT(L9,1)))) | P9: Pruebas en el API TEST
A10: 6 | B10: R35 | C10: =IFERROR(VLOOKUP(B10,'Matriz de riesgos'!$A:$B,2,0),"") | D10: =IFERROR(VLOOKUP(B10,'Matriz de riesgos'!$A:$O,15,0),"") | E10: 1. Elección de controles | F10: Cambio en código fuente | G10: Jefe de Desarrollo | H10: Enero 2025 | I10: Marzo 2025 | J10: Humano Tecnológico | K10: En tratamiento | N10: =IF(OR(L10="",M10=""),"",INDEX('Datos maestros'!$B$162:$F$165,VALUE(LEFT(M10,1)),VALUE(LEFT(L10,1)))) | P10: Elaborar propuesta a debatir Creación de BD múltiples con esquemas
A11: 7 | B11: R39 | C11: =IFERROR(VLOOKUP(B11,'Matriz de riesgos'!$A:$B,2,0),"") | D11: =IFERROR(VLOOKUP(B11,'Matriz de riesgos'!$A:$O,15,0),"") | E11: 1. Elección de controles | F11: Planificación de beneficios sociales a los colaboradores | G11: Gerente general | H11: Abril 2024 | I11: Agosto 2024 | J11: Humano Financiero | K11: Mitigado / Cerrado | N11: =IF(OR(L11="",M11=""),"",INDEX('Datos maestros'!$B$162:$F$165,VALUE(LEFT(M11,1)),VALUE(LEFT(L11,1)))) | P11: - Fortalecimiento en la cultura organizacional, - Trabajo en equipo, - Sábados libres para todo el 2024 - Beneficios económicos de dividendos (trimestral)
A12: 13 | B12: R46 | C12: =IFERROR(VLOOKUP(B12,'Matriz de riesgos'!$A:$B,2,0),"") -> Validación de comprobantes OSE | D12: =IFERROR(VLOOKUP(B12,'Matriz de riesgos'!$A:$O,15,0),"") -> Alto | E12: 1. Elección de controles | F12: Nuevo desarrollo para pruebas unitarias en el servicio OSE | G12: Desarrollador OSE | H12: Mayo 2025 | I12: Octubre 2026 | J12: Tecnológico Humano | K12: Pendiente | N12: =IF(OR(L12="",M12=""),"",INDEX('Datos maestros'!$B$162:$F$165,VALUE(LEFT(M12,1)),VALUE(LEFT(L12,1)))) | P12: Nuevo desarrollo en DevOps y Pipeline
A13: 14 | B13: R48 | C13: =IFERROR(VLOOKUP(B13,'Matriz de riesgos'!$A:$B,2,0),"") -> Gestion de operaciones | D13: =IFERROR(VLOOKUP(B13,'Matriz de riesgos'!$A:$O,15,0),"") -> Alto | E13: 1. Elección de controles | F13: Implementación de despliegues controlados mediante pipeline (DevOps) y pruebas automáticas en los módulos críticos del ERP: Pipeline de integración y despliegue continuo: compilación, ejecución de pruebas y despliegue por etapas (Desarrollo → QA → Producción), con aprobación previa antes del pase a producción. Pruebas automáticas (unitarias y de regresión) en los módulos críticos: ventas, emisión de comprobantes y contabilidad. El pipeline bloquea el despliegue si alguna prueba falla. Reversión (rollback) de la versión desde el pipeline ante fallas detectadas en producción. | G13: Jefe de Desarrollo | H13: Mayo 2025 | I13: Octubre 2026 | J13: Recursos humanos Recursos tecnológico | K13: En tratamiento | N13: =IF(OR(L13="",M13=""),"",INDEX('Datos maestros'!$B$162:$F$165,VALUE(LEFT(M13,1)),VALUE(LEFT(L13,1)))) | P13: Nuevo desarrollo en DevOps y Pipeline
A14: 15 | B14: R49 | C14: =IFERROR(VLOOKUP(B14,'Matriz de riesgos'!$A:$B,2,0),"") -> Gestión del éxito y atención del cliente | D14: =IFERROR(VLOOKUP(B14,'Matriz de riesgos'!$A:$O,15,0),"") -> Alto | E14: 1. Elección de controles | F14: Contratación de Analistas e Ingenieros de Soporte al cliente Retomar sábados libre Separación de área de Soporte (Help Desk y Ingeniería de Soporte al cliente) | G14: Gerente general | H14: Mayo 2025 | I14: Setiembre 2025 | J14: Recursos humanos Recursos financieros | K14: Mitigado / Cerrado | L14: 3 - Serio | M14: 2 – Bastante improbable | N14: =IF(OR(L14="",M14=""),"",INDEX('Datos maestros'!$B$162:$F$165,VALUE(LEFT(M14,1)),VALUE(LEFT(L14,1)))) -> Bajo | O14: 45870 | P14: Contratación de Analistas e Ingenieros de Soporte al cliente Retomar sábados libre Separación de área de Soporte (Help Desk y Ingeniería de Soporte al cliente)
A15: 16 | B15: R50 | C15: =IFERROR(VLOOKUP(B15,'Matriz de riesgos'!$A:$B,2,0),"") -> Facturación y cobranza | D15: =IFERROR(VLOOKUP(B15,'Matriz de riesgos'!$A:$O,15,0),"") -> Alto | E15: 1. Elección de controles | F15: Contratación del servicio de Equifax para la evaluación crediticia de clientes: 1) Consulta obligatoria del reporte crediticio (score, calificación SBS, deudas vigentes, protestos y morosidad) antes de aprobar ventas o servicios al crédito y en cada renovación de contrato. 2) Criterios de decisión según el resultado de la consulta: aprobar al crédito, solicitar adelanto/garantía o aceptar solo pago al contado. | G15: Gerente general | H15: Mayo 2025 | I15: Setiembre 2025 | J15: Recursos humanos Recursos financieros | K15: Mitigado / Cerrado | L15: 3 - Serio | M15: 2 – Bastante improbable | N15: =IF(OR(L15="",M15=""),"",INDEX('Datos maestros'!$B$162:$F$165,VALUE(LEFT(M15,1)),VALUE(LEFT(L15,1)))) -> Bajo | O15: 45778 | P15: Servicio Equifax contratado e implementado. La consulta previa reduce la probabilidad de otorgar crédito a clientes con mala calificación; la consecuencia se mantiene ante un eventual impago. Evidencia: contrato/orden de servicio con Equifax, reportes de consulta por cliente y comparativo de los reportes de morosidad antes y después de la implementación.
A16: 17 | B16: R51 | C16: =IFERROR(VLOOKUP(B16,'Matriz de riesgos'!$A:$B,2,0),"") -> Gestion de operaciones | D16: =IFERROR(VLOOKUP(B16,'Matriz de riesgos'!$A:$O,15,0),"") -> Alto | E16: 1. Elección de controles | F16: 1) Migración de credenciales a Azure Key Vault, implementada para el módulo de facturación electrónica. 2) Cifrado mediante tag, aplicable únicamente a servidores on-premise. 3) Sistema web propio de gestión y control de cambios de credenciales: registra altas y modificaciones, oculta el valor con asteriscos mostrándolo solo al momento de su generación, y genera automáticamente el control de vigencia/rotación a partir de la fecha de caducidad indicada. Desarrollado y disponible, pendiente de capacitación al equipo y puesta en producción. | G16: Asistente Administrativo | H16: 45778 | I16: 45992 | J16: Recursos humanos Recurso tecnológico | K16: En tratamiento | L16: 4 - Crítico | M16: 1 - Improbable | N16: =IF(OR(L16="",M16=""),"",INDEX('Datos maestros'!$B$162:$F$165,VALUE(LEFT(M16,1)),VALUE(LEFT(L16,1)))) -> Bajo | P16: Cobertura parcial a la fecha: Key Vault aplicado solo a facturación electrónica y cifrado por tag solo en servidores on-premise; las credenciales de otras integraciones permanecen en archivo Excel hasta el pase a producción del sistema web de control de cambios. Pendiente reunión de capacitación (segunda convocatoria) e implementación.
A17: =IF(B17="","",ROW()-4) -> 13 | B17: R52 | C17: =IFERROR(VLOOKUP(B17,'Matriz de riesgos'!$A:$B,2,0),"") -> Gestión del éxito y atención del cliente | D17: =IFERROR(VLOOKUP(B17,'Matriz de riesgos'!$A:$O,15,0),"") -> Medio | E17: 1. Elección de controles | F17: (BUG 6104 Revisar devolución de bonificados de combos en opción rechazos clientes) - ANTAM (Bug 7084: No validar stock de lote cuando el config 302 está activo) - ELSUPER | G17: Jefe de Desarrollo | H17: 46113 | I17: 46174 | J17: Recursos humanos Recurso tecnológico | K17: Mitigado / Cerrado | L17: 2 - Significativo | M17: 2 – Bastante improbable | N17: =IF(OR(L17="",M17=""),"",INDEX('Datos maestros'!$B$162:$F$165,VALUE(LEFT(M17,1)),VALUE(LEFT(L17,1)))) -> Bajo | O17: 46283 | P17: Corrección puntual por cliente afectado (ANTAM, ELSUPER); pendiente confirmar si existen otros módulos con el mismo patrón de incompatibilidad de tipos de datos tras la migración a .NET Standard.
A18: =IF(B18="","",ROW()-4) -> 14 | B18: R53 | C18: =IFERROR(VLOOKUP(B18,'Matriz de riesgos'!$A:$B,2,0),"") -> Ingenieria y calidad de sofware | D18: =IFERROR(VLOOKUP(B18,'Matriz de riesgos'!$A:$O,15,0),"") -> Alto | E18: 1. Elección de controles | F18: PRODUCT BACKLOG ITEM 6598: Validar DNI al registrar una guía de remisión Contratación de API de consulta a RENIEC que llena y actualiza automaticamente el padrón interno (bd RENIEC) | G18: Jefe de Desarrollo | H18: 46143 | I18: 46204 | J18: Recursos humanos Recurso tecnológico | K18: Mitigado / Cerrado | L18: 1 - Menor | M18: 1 - Improbable | N18: =IF(OR(L18="",M18=""),"",INDEX('Datos maestros'!$B$162:$F$165,VALUE(LEFT(M18,1)),VALUE(LEFT(L18,1)))) -> Muy bajo | O18: 46258 | P18: Control inexistente al momento de la identificación del riesgo; implementado posteriormente mediante API de actualización del padrón.
A19: 20 | B19: R54 | C19: =IFERROR(VLOOKUP(B19,'Matriz de riesgos'!$A:$B,2,0),"") -> Ingenieria y calidad de sofware | D19: =IFERROR(VLOOKUP(B19,'Matriz de riesgos'!$A:$O,15,0),"") -> Alto | E19: 1. Elección de controles | F19: Mejoras en las directivas DLP | G19: Jefe de Producción | H19: 46266 | I19: 46327 | N19: =IF(OR(L19="",M19=""),"",INDEX('Datos maestros'!$B$162:$F$165,VALUE(LEFT(M19,1)),VALUE(LEFT(L19,1))))
A20: 21 | B20: R55 | C20: =IFERROR(VLOOKUP(B20,'Matriz de riesgos'!$A:$B,2,0),"") -> Gestion de operaciones | D20: =IFERROR(VLOOKUP(B20,'Matriz de riesgos'!$A:$O,15,0),"") -> Alto | E20: 1. Elección de controles | F20: Portal de status de los servicios de SIEMPRESOFT | G20: Jefe de Producción | H20: 46266 | I20: 46296 | J20: Recursos humanos Recurso tecnológico Recursos financieros | K20: En tratamiento | N20: =IF(OR(L20="",M20=""),"",INDEX('Datos maestros'!$B$162:$F$165,VALUE(LEFT(M20,1)),VALUE(LEFT(L20,1))))
A21: 22 | B21: R57 | C21: =IFERROR(VLOOKUP(B21,'Matriz de riesgos'!$A:$B,2,0),"") -> Infraestructura tecnológica | D21: =IFERROR(VLOOKUP(B21,'Matriz de riesgos'!$A:$O,15,0),"") -> Alto | E21: 1. Elección de controles | F21: Incorporar al procedimiento de TI revisión obligatoria de los problemas conocidos (known issues) publicados por el proveedor antes de instalar actualizaciones acumulativas del SO tanto al servidor QA como a VM de producción. Incluye deshabilitar Windows Update automático en la VM recién creada hasta completar dicha verificación. | G21: Jefe de Producción | H21: 46266 | I21: 46296 | J21: Recursos humanos | K21: En tratamiento | N21: =IF(OR(L21="",M21=""),"",INDEX('Datos maestros'!$B$162:$F$165,VALUE(LEFT(M21,1)),VALUE(LEFT(L21,1))))
A22: =IF(B22="","",ROW()-4) | C22: =IFERROR(VLOOKUP(B22,'Matriz de riesgos'!$A:$B,2,0),"") | D22: =IFERROR(VLOOKUP(B22,'Matriz de riesgos'!$A:$O,15,0),"") | N22: =IF(OR(L22="",M22=""),"",INDEX('Datos maestros'!$B$162:$F$165,VALUE(LEFT(M22,1)),VALUE(LEFT(L22,1))))
A23: =IF(B23="","",ROW()-4) | C23: =IFERROR(VLOOKUP(B23,'Matriz de riesgos'!$A:$B,2,0),"") | D23: =IFERROR(VLOOKUP(B23,'Matriz de riesgos'!$A:$O,15,0),"") | N23: =IF(OR(L23="",M23=""),"",INDEX('Datos maestros'!$B$162:$F$165,VALUE(LEFT(M23,1)),VALUE(LEFT(L23,1))))
A24: =IF(B24="","",ROW()-4) | C24: =IFERROR(VLOOKUP(B24,'Matriz de riesgos'!$A:$B,2,0),"") | D24: =IFERROR(VLOOKUP(B24,'Matriz de riesgos'!$A:$O,15,0),"") | N24: =IF(OR(L24="",M24=""),"",INDEX('Datos maestros'!$B$162:$F$165,VALUE(LEFT(M24,1)),VALUE(LEFT(L24,1))))
A25: =IF(B25="","",ROW()-4) | C25: =IFERROR(VLOOKUP(B25,'Matriz de riesgos'!$A:$B,2,0),"") | D25: =IFERROR(VLOOKUP(B25,'Matriz de riesgos'!$A:$O,15,0),"") | N25: =IF(OR(L25="",M25=""),"",INDEX('Datos maestros'!$B$162:$F$165,VALUE(LEFT(M25,1)),VALUE(LEFT(L25,1))))
A26: =IF(B26="","",ROW()-4) | C26: =IFERROR(VLOOKUP(B26,'Matriz de riesgos'!$A:$B,2,0),"") | D26: =IFERROR(VLOOKUP(B26,'Matriz de riesgos'!$A:$O,15,0),"") | N26: =IF(OR(L26="",M26=""),"",INDEX('Datos maestros'!$B$162:$F$165,VALUE(LEFT(M26,1)),VALUE(LEFT(L26,1))))
A27: =IF(B27="","",ROW()-4) | C27: =IFERROR(VLOOKUP(B27,'Matriz de riesgos'!$A:$B,2,0),"") | D27: =IFERROR(VLOOKUP(B27,'Matriz de riesgos'!$A:$O,15,0),"") | N27: =IF(OR(L27="",M27=""),"",INDEX('Datos maestros'!$B$162:$F$165,VALUE(LEFT(M27,1)),VALUE(LEFT(L27,1))))
A28: =IF(B28="","",ROW()-4) | C28: =IFERROR(VLOOKUP(B28,'Matriz de riesgos'!$A:$B,2,0),"") | D28: =IFERROR(VLOOKUP(B28,'Matriz de riesgos'!$A:$O,15,0),"") | N28: =IF(OR(L28="",M28=""),"",INDEX('Datos maestros'!$B$162:$F$165,VALUE(LEFT(M28,1)),VALUE(LEFT(L28,1))))
A29: =IF(B29="","",ROW()-4) | C29: =IFERROR(VLOOKUP(B29,'Matriz de riesgos'!$A:$B,2,0),"") | D29: =IFERROR(VLOOKUP(B29,'Matriz de riesgos'!$A:$O,15,0),"") | N29: =IF(OR(L29="",M29=""),"",INDEX('Datos maestros'!$B$162:$F$165,VALUE(LEFT(M29,1)),VALUE(LEFT(L29,1))))
A30: =IF(B30="","",ROW()-4) | C30: =IFERROR(VLOOKUP(B30,'Matriz de riesgos'!$A:$B,2,0),"") | D30: =IFERROR(VLOOKUP(B30,'Matriz de riesgos'!$A:$O,15,0),"") | N30: =IF(OR(L30="",M30=""),"",INDEX('Datos maestros'!$B$162:$F$165,VALUE(LEFT(M30,1)),VALUE(LEFT(L30,1))))
A31: =IF(B31="","",ROW()-4) | C31: =IFERROR(VLOOKUP(B31,'Matriz de riesgos'!$A:$B,2,0),"") | D31: =IFERROR(VLOOKUP(B31,'Matriz de riesgos'!$A:$O,15,0),"") | N31: =IF(OR(L31="",M31=""),"",INDEX('Datos maestros'!$B$162:$F$165,VALUE(LEFT(M31,1)),VALUE(LEFT(L31,1))))
A32: =IF(B32="","",ROW()-4) | C32: =IFERROR(VLOOKUP(B32,'Matriz de riesgos'!$A:$B,2,0),"") | D32: =IFERROR(VLOOKUP(B32,'Matriz de riesgos'!$A:$O,15,0),"") | N32: =IF(OR(L32="",M32=""),"",INDEX('Datos maestros'!$B$162:$F$165,VALUE(LEFT(M32,1)),VALUE(LEFT(L32,1))))
A33: =IF(B33="","",ROW()-4) | C33: =IFERROR(VLOOKUP(B33,'Matriz de riesgos'!$A:$B,2,0),"") | D33: =IFERROR(VLOOKUP(B33,'Matriz de riesgos'!$A:$O,15,0),"") | N33: =IF(OR(L33="",M33=""),"",INDEX('Datos maestros'!$B$162:$F$165,VALUE(LEFT(M33,1)),VALUE(LEFT(L33,1))))
... A45: =IF(B45="","",ROW()-4) | C45: =IFERROR(VLOOKUP(B45,'Matriz de riesgos'!$A:$B,2,0),"") | D45: =IFERROR(VLOOKUP(B45,'Matriz de riesgos'!$A:$O,15,0),"") | N45: =IF(OR(L45="",M45=""),"",INDEX('Datos maestros'!$B$162:$F$165,VALUE(LEFT(M45,1)),VALUE(LEFT(L45,1))))
